Workbook

Sheet Raw Data - Facewash
A1: FACEWASH — MT vs GT Raw Extract (Nielsen/Kantar Retail Audit Panel, URB)
A3: Channel | B3: Item | C3: Metric | D3: Jun'25 | E3: Jun'26 | F3: L3M YA | G3: L3M (Apr-Jun'26) | H3: L12M YA | I3: L12M (Jul'25-Jun'26)
A4: MT | B4: Category | C4: Sales Value (Crs.) | D4: 71.2 | E4: 82.2 | F4: 210.5 | G4: 241.3 | H4: 780.3 | I4: 857.7
A5: MT | B5: Category | C5: MS Val | D5: 100 | E5: 100 | F5: 100 | G5: 100 | H5: 100 | I5: 100
A6: MT | B6: Category | C6: MS Vol | D6: 100 | E6: 100 | F6: 100 | G6: 100 | H6: 100 | I6: 100
A7: MT | B7: Category | C7: Number of Stores Retailing | D7: 20657.1 | E7: 22129.8 | F7: 21191.5 | G7: 22483.4 | H7: 21710.8 | I7: 22512.5
A8: MT | B8: Category | C8: Wghtd Dist Handling | D8: 100 | E8: 100 | F8: 100 | G8: 100 | H8: 100 | I8: 100
A9: MT | B9: Category | C9: Per Dealer Offtake (PDO) (Value) | D9: 34447.8 | E9: 37124.1 | F9: 33104.1 | G9: 35767.4 | H9: 29950.5 | I9: 31747.4
A10: MT | B10: Category | C10: Price per ml | D10: 1.4 | E10: 1.4 | F10: 1.4 | G10: 1.5 | H10: 1.4 | I10: 1.4
A11: MT | B11: Mamaearth | C11: Sales Value (Crs.) | D11: 6 | E11: 9.5 | F11: 17.6 | G11: 27.9 | H11: 58.1 | I11: 90.2
A12: MT | B12: Mamaearth | C12: MS Val | D12: 8.5 | E12: 11.6 | F12: 8.4 | G12: 11.6 | H12: 7.5 | I12: 10.5
A13: MT | B13: Mamaearth | C13: MS Vol | D13: 7.6 | E13: 10.9 | F13: 7.8 | G13: 10.9 | H13: 6.8 | I13: 9.9
A14: MT | B14: Mamaearth | C14: Number of Stores Retailing | D14: 10005.8 | E14: 13162.7 | F14: 12201 | G14: 14620.2 | H14: 13704.1 | I14: 15234.6
A15: MT | B15: Mamaearth | C15: Wghtd Dist Handling | D15: 78.7 | E15: 87 | F15: 83 | G15: 89 | H15: 85.9 | I15: 89.8
... A31: GT | B31: Mamaearth | C31: Price per ml | D31: 2.5 | E31: 2.6 | F31: 2.5 | G31: 2.6 | H31: 2.5 | I31: 2.6
A33: Source: Facewash_Shampoo_Snapshot_Report_June_26.csv. MT = AI (U+R) MT panel, GT = GT Total panel. Extracted values, no manual edits.

Sheet Raw Data - Shampoo
A1: SHAMPOO — MT vs GT Raw Extract (Nielsen/Kantar Retail Audit Panel, URB)
A3: Channel | B3: Item | C3: Metric | D3: Jun'25 | E3: Jun'26 | F3: L3M YA | G3: L3M (Apr-Jun'26) | H3: L12M YA | I3: L12M (Jul'25-Jun'26)
A4: MT | B4: Category | C4: Sales Value (Crs.) | D4: 139.8 | E4: 155.3 | F4: 429.4 | G4: 462 | H4: 1736.4 | I4: 1736.4
A5: MT | B5: Category | C5: MS Val | D5: 100 | E5: 100 | F5: 100 | G5: 100 | H5: 100 | I5: 100
A6: MT | B6: Category | C6: MS Vol | D6: 100 | E6: 100 | F6: 100 | G6: 100 | H6: 100 | I6: 100
A7: MT | B7: Category | C7: Number of Stores Retailing | D7: 20864.8 | E7: 22648.9 | F7: 21323.9 | G7: 22643.5 | H7: 21881.9 | I7: 22807.1
A8: MT | B8: Category | C8: Wghtd Dist Handling | D8: 100 | E8: 100 | F8: 100 | G8: 100 | H8: 100 | I8: 100
A9: MT | B9: Category | C9: Per Dealer Offtake (PDO) (Value) | D9: 66994.5 | E9: 68586.1 | F9: 67130.7 | G9: 68005.5 | H9: 66128.6 | I9: 63443.5
A10: MT | B10: Category | C10: Price per ml | D10: 0.8 | E10: 0.7 | F10: 0.8 | G10: 0.7 | H10: 0.7 | I10: 0.7
A11: MT | B11: Mamaearth | C11: Sales Value (Crs.) | D11: 3.2 | E11: 6.2 | F11: 10.3 | G11: 18.6 | H11: 42.8 | I11: 63.5
A12: MT | B12: Mamaearth | C12: MS Val | D12: 2.3 | E12: 4 | F12: 2.4 | G12: 4 | H12: 2.5 | I12: 3.7
A13: MT | B13: Mamaearth | C13: MS Vol | D13: 2.3 | E13: 4.3 | F13: 2.5 | G13: 4.4 | H13: 2.3 | I13: 4.1
A14: MT | B14: Mamaearth | C14: Number of Stores Retailing | D14: 7572.8 | E14: 8883.3 | F14: 9023.7 | G14: 10335.2 | H14: 10836.4 | I14: 12070.8
A15: MT | B15: Mamaearth | C15: Wghtd Dist Handling | D15: 73.5 | E15: 78.3 | F15: 78.6 | G15: 81.5 | H15: 85.9 | I15: 86.4
... A31: GT | B31: Mamaearth | C31: Price per ml | D31: 1.3 | E31: 1.2 | F31: 1.3 | G31: 1.2 | H31: 1.3 | I31: 1.3
A33: Source: Honasa_Shampoo_Subbrand_Report_Monthly_June_26.csv. Category row = blank BRAND/SUBBRAND (category total).

Sheet Pack Mix - Shampoo
A1: SHAMPOO PACK MIX — MT vs GT (Sales Value, Jun'26)
A3: Channel | B3: Base Pack Size (ml) | C3: Sales Value Jun'26 (Cr)
A4: MT | B4: 650 | C4: 41.4
A5: MT | B5: 180 | C5: 22.2
A6: MT | B6: 340 | C6: 22.2
A7: MT | B7: 1000 | C7: 20.1
A8: MT | B8: 200 | C8: 6.7
A9: MT | B9: 400 | C9: 6.7
A10: MT | B10: 580 | C10: 6.1
A11: MT | B11: 175 | C11: 4.2
A12: GT | B12: 180 | C12: 25.3
A13: GT | B13: 100 | C13: 16.4
A14: GT | B14: 200 | C14: 13.3
A15: GT | B15: 340 | C15: 9.2
... A19: GT | B19: 1000 | C19: 5.1
A21: Source: Honasa_Shampoo_Base_Pack_Size_Monthly_June_26.csv. Top 8 packs by value per channel.

Sheet Nielsen Competitor & State
A1: NIELSEN COMPETITIVE, PACK & STATE READOUT — National Urban, May'26 (separate source, not MT/GT split)
A3: FACEWASH — Top competitors (National Urban Nielsen MS Val, May'26)
A4: Rank | B4: Brand | C4: Value (Cr) | D4: YoY Val % | E4: MS Val % | F4: MoM (bps) | G4: YoY (bps) | H4: Wtd Dist %
A5: 1 | B5: Himalaya | C5: 17.9 | D5: -2 | E5: 22 | F5: 20 | G5: -328 | H5: 100
A6: 2 | B6: Garnier | C6: 11.8 | D6: 17 | E6: 14 | F6: 43 | G6: 55 | H6: 90
A7: 3 | B7: Pond's | C7: 11.4 | D7: 8 | E7: 14 | F7: -114 | G7: -61 | H7: 98
A8: 4 | B8: Mamaearth | C8: 9.6 | D8: 54 | E8: 12 | F8: 0 | G8: 311 | H8: 87
A9: 5 | B9: Clean & Clear | C9: 6.3 | D9: 16 | E9: 8 | F9: 3 | G9: 22 | H9: 97
A10: 6 | B10: Joy | C10: 4.9 | D10: 7 | E10: 6 | F10: 7 | G10: -30 | H10: 76
A11: 7 | B11: Lakme | C11: 3.1 | D11: 23 | E11: 4 | F11: 60 | G11: 31 | H11: 79
A12: 8 | B12: Nivea Men | C12: 3 | D12: -2 | E12: 4 | F12: -7 | G12: -54 | H12: 86
A13: 9 | B13: Simple | C13: 1.9 | E13: 2 | F13: 36 | G13: 223 | H13: 51
A14: 16 | B14: The Derma Co | C14: 0.606 | D14: 3940 | E14: 0.7 | F14: 6 | G14: 71 | H14: 14
A16: SHAMPOO — Top competitors (National Urban Nielsen MS Val, May'26)
A17: Rank | B17: Brand | C17: Value (Cr) | D17: YoY Val % | E17: MS Val % | F17: MoM (bps) | G17: YoY (bps) | H17: Wtd Dist %
A18: 1 | B18: Dove | C18: 29.6 | D18: 7 | E18: 18 | F18: 170 | G18: 20 | H18: 99
A19: 2 | B19: L'Oreal Paris | C19: 22.1 | D19: 20 | E19: 13 | F19: 70 | G19: 130 | H19: 91
A20: 3 | B20: Head & Shoulders | C20: 19 | D20: -8 | E20: 11 | F20: 130 | G20: 200 | H20: 99
A21: 4 | B21: Tresemme | C21: 17.3 | D21: 25 | E21: 10 | F21: 90 | G21: 140 | H21: 98
A22: 5 | B22: Clinic Plus | C22: 16.7 | D22: 14 | E22: 10 | F22: 30 | G22: 50 | H22: 99
A23: 6 | B23: Sunsilk | C23: 14.8 | D23: -7 | E23: 9 | F23: 0 | G23: 150 | H23: 99
A24: 7 | B24: Mamaearth | C24: 6.5 | D24: 64 | E24: 4 | F24: 30 | G24: 130 | H24: 81
A25: 8 | B25: Pantene | C25: 6.5 | D25: -4 | E25: 4 | F25: 30 | G25: 50 | H25: 96
A26: 9 | B26: Himalaya | C26: 5.7 | D26: 2 | E26: 3 | F26: 40 | G26: 20 | H26: 91
A28: Mamaearth Facewash — pack size (National Urban, May'26)
A29: Rank | B29: Pack | C29: Contribution % | D29: MoM (bps) | E29: YoY (bps) | F29: Value (Cr) | G29: YoY Growth %
A30: 1 | B30: 150ml | C30: 58 | D30: -40 | E30: 290 | F30: 5.53 | G30: 98
A31: 2 | B31: 100ml | C31: 21 | D31: -40 | E31: -60 | F31: 1.96 | G31: -11
A32: 3 | B32: 200ml | C32: 11 | D32: 90 | E32: 130 | F32: 1.06
A33: 4 | B33: 50ml | C33: 11 | D33: -10 | E33: 50 | F33: 1.01 | G33: 80
A34: 5 | B34: 250ml | C34: 0 | D34: 0 | E34: -80 | F34: 0.04 | G34: -94
A36: High-contribution, low-share states — distribution white space (May'26)
A37: Category | B37: State | C37: Contribution to Category % | D37: May'26 Share % | E37: MoM (bps)
A38: Facewash | B38: Uttar Pradesh | C38: 15 | D38: 6 | E38: -122
A39: Facewash | B39: Maharashtra | C39: 14 | D39: 6 | E39: 16
A40: Facewash | B40: West Bengal | C40: 8 | D40: 5 | E40: 28
A41: Facewash | B41: Delhi | C41: 8 | D41: 9 | E41: -42
A42: Facewash | B42: Haryana | C42: 6 | D42: 8 | E42: 148
A43: Facewash | B43: Madhya Pradesh | C43: 6 | D43: 7 | E43: 14
A44: Facewash | B44: Bihar | C44: 6 | D44: 5 | E44: -15
...

Sheet MT vs GT Summary
A1: MT vs GT PERFORMANCE SUMMARY — Facewash & Shampoo (Mamaearth), as of Jun'26
A3: FACEWASH
A4: Metric | B4: MT | C4: GT | D4: Note
A5: Category value growth (L12M) | B5: ==('Raw Data - Facewash'!I4-'Raw Data - Facewash'!H4)/'Raw Data - Facewash'!H4 | C5: ==('Raw Data - Facewash'!I18-'Raw Data - Facewash'!H18)/'Raw Data - Facewash'!H18
A6: Mamaearth value growth (L12M) | B6: ==('Raw Data - Facewash'!I11-'Raw Data - Facewash'!H11)/'Raw Data - Facewash'!H11 | C6: ==('Raw Data - Facewash'!I25-'Raw Data - Facewash'!H25)/'Raw Data - Facewash'!H25
A7: Mamaearth value growth (L3M) | B7: ==('Raw Data - Facewash'!G11-'Raw Data - Facewash'!F11)/'Raw Data - Facewash'!F11 | C7: ==('Raw Data - Facewash'!G25-'Raw Data - Facewash'!F25)/'Raw Data - Facewash'!F25
A8: Mamaearth value growth (Jun vs Jun LY) | B8: ==('Raw Data - Facewash'!E11-'Raw Data - Facewash'!D11)/'Raw Data - Facewash'!D11 | C8: ==('Raw Data - Facewash'!E25-'Raw Data - Facewash'!D25)/'Raw Data - Facewash'!D25
A9: Mamaearth Market Share Val — latest (%) | B9: =='Raw Data - Facewash'!I12/100 | C9: =='Raw Data - Facewash'!I26/100
A10: Mamaearth Market Share Val — change (pp, L12M) | B10: ==('Raw Data - Facewash'!I12-'Raw Data - Facewash'!H12)/100 | C10: ==('Raw Data - Facewash'!I26-'Raw Data - Facewash'!H26)/100
A11: Mamaearth Weighted Distribution — latest (%) | B11: =='Raw Data - Facewash'!I15/100 | C11: =='Raw Data - Facewash'!I29/100
A12: Mamaearth Weighted Distribution — change (pp, L12M) | B12: ==('Raw Data - Facewash'!I15-'Raw Data - Facewash'!H15)/100 | C12: ==('Raw Data - Facewash'!I29-'Raw Data - Facewash'!H29)/100
A13: Mamaearth # Stores Retailing — growth (L12M) | B13: ==('Raw Data - Facewash'!I14-'Raw Data - Facewash'!H14)/'Raw Data - Facewash'!H14 | C13: ==('Raw Data - Facewash'!I28-'Raw Data - Facewash'!H28)/'Raw Data - Facewash'!H28
A14: Mamaearth PDO (₹/dealer) — growth (L12M) | B14: ==('Raw Data - Facewash'!I16-'Raw Data - Facewash'!H16)/'Raw Data - Facewash'!H16 | C14: ==('Raw Data - Facewash'!I30-'Raw Data - Facewash'!H30)/'Raw Data - Facewash'!H30
A16: SHAMPOO
A17: Metric | B17: MT | C17: GT | D17: Note
A18: Category value growth (L12M) | B18: ==('Raw Data - Shampoo'!I4-'Raw Data - Shampoo'!H4)/'Raw Data - Shampoo'!H4 | C18: ==('Raw Data - Shampoo'!I18-'Raw Data - Shampoo'!H18)/'Raw Data - Shampoo'!H18
A19: Mamaearth value growth (L12M) | B19: ==('Raw Data - Shampoo'!I11-'Raw Data - Shampoo'!H11)/'Raw Data - Shampoo'!H11 | C19: ==('Raw Data - Shampoo'!I25-'Raw Data - Shampoo'!H25)/'Raw Data - Shampoo'!H25
A20: Mamaearth value growth (L3M) | B20: ==('Raw Data - Shampoo'!G11-'Raw Data - Shampoo'!F11)/'Raw Data - Shampoo'!F11 | C20: ==('Raw Data - Shampoo'!G25-'Raw Data - Shampoo'!F25)/'Raw Data - Shampoo'!F25
A21: Mamaearth value growth (Jun vs Jun LY) | B21: ==('Raw Data - Shampoo'!E11-'Raw Data - Shampoo'!D11)/'Raw Data - Shampoo'!D11 | C21: ==('Raw Data - Shampoo'!E25-'Raw Data - Shampoo'!D25)/'Raw Data - Shampoo'!D25
A22: Mamaearth Market Share Val — latest (%) | B22: =='Raw Data - Shampoo'!I12/100 | C22: =='Raw Data - Shampoo'!I26/100
A23: Mamaearth Market Share Val — change (pp, L12M) | B23: ==('Raw Data - Shampoo'!I12-'Raw Data - Shampoo'!H12)/100 | C23: ==('Raw Data - Shampoo'!I26-'Raw Data - Shampoo'!H26)/100
A24: Mamaearth Weighted Distribution — latest (%) | B24: =='Raw Data - Shampoo'!I15/100 | C24: =='Raw Data - Shampoo'!I29/100
A25: Mamaearth Weighted Distribution — change (pp, L12M) | B25: ==('Raw Data - Shampoo'!I15-'Raw Data - Shampoo'!H15)/100 | C25: ==('Raw Data - Shampoo'!I29-'Raw Data - Shampoo'!H29)/100
A26: Mamaearth # Stores Retailing — growth (L12M) | B26: ==('Raw Data - Shampoo'!I14-'Raw Data - Shampoo'!H14)/'Raw Data - Shampoo'!H14 | C26: ==('Raw Data - Shampoo'!I28-'Raw Data - Shampoo'!H28)/'Raw Data - Shampoo'!H28
A27: Mamaearth PDO (₹/dealer) — growth (L12M) | B27: ==('Raw Data - Shampoo'!I16-'Raw Data - Shampoo'!H16)/'Raw Data - Shampoo'!H16 | C27: ==('Raw Data - Shampoo'!I30-'Raw Data - Shampoo'!H30)/'Raw Data - Shampoo'!H30
A29: All growth %/pp figures are formulas linking to the Raw Data tabs — they recalculate if source values are edited. pp = percentage points.

Sheet Action Tracker
A1: MT vs GT — ACTION TRACKER
A3: Objective | B3: Key Result / KPI | C3: Owner | D3: Timeline | E3: Status | F3: Next Action | G3: Review Rhythm
A4: Fix GT Shampoo distribution loss | B4: Restore stores retailing to ≥73,000 (from 66,750) | C4: GT Sales / DMS Team | D4: Aug'26 | E4: Not Started | F4: Pull stockist-level DMS billing to isolate de-listing vs non-servicing vs secondary sales gap | G4: Weekly
A5: Correct GT Shampoo pack mix | B5: List 340ml/650ml SKUs in top 20 GT chains | C5: RKAM / GT Category | D5: Sep'26 | E5: Not Started | F5: Audit current GT listing vs MT pack assortment | G5: Bi-weekly
A6: Scale MT merchandising learnings to GT | B6: Pilot MT visibility/PDO playbook in 20 GT towns | C6: Trade Marketing | D6: Sep'26 | E6: Not Started | F6: Document MT merchandising SOP driving PDO growth | G6: Monthly
A7: Sustain MT facewash/shampoo momentum | B7: Keep fill-rate ≥95% as store count scales +30% | C7: NKAM / MT Team | D7: Ongoing | E7: On Track | F7: Ensure NPD listing keeps pace with new store additions | G7: Monthly
A8: Re-baseline FY27 GT Shampoo plan | B8: Revised target reflecting -22.8% LTM decline | C8: Category Lead | D8: Before FY27 QBR | E8: Not Started | F8: Flag to leadership ahead of QBR to avoid missed-plan surprise | G8: Quarterly
A9: Close UP/Maharashtra distribution white space | B9: Raise Nielsen share in UP & Maharashtra toward category-contribution level | C9: RKAM / Zone Sales | D9: Q3 FY27 | E9: Not Started | F9: Prioritize new-store/visibility spend in UP & Maharashtra; both states are high category-contribution, low Nielsen-share in Facewash and Shampoo | G9: Quarterly
