Workbook

Sheet Executive Dashboard
A1: EXECUTIVE DASHBOARD · S&OP one-page (₹ Cr)
A2: Honasa / Mamaearth · Modern Trade · rolling 3-month demand & supply view — recomputes from the Control Panel
A4: Scenario | D4: Forecast Window | G4: Selected 3M Forecast | J4: 3M Target
A5: ='Control Panel'!$B$5 | D5: ='Control Panel'!$B$4&" → "&'Control Panel'!$B$7 | G5: ='Forecast Engine'!$AT$13+'Forecast Engine'!$AU$13+'Forecast Engine'!$AV$13 | J5: =SUMIFS('Monthly Target Upload'!$D$4:$D$15,'Monthly Target Upload'!$A$4:$A$15,'Control Panel'!$B$4)+SUMIFS('Monthly Target Upload'!$D$4:$D$15,'Monthly Target Upload'!$A$4:$A$15,'Control Panel'!$B$6)+SUMIFS('Monthly Target Upload'!$D$4:$D$15,'Monthly Target Upload'!$A$4:$A$15,'Control Panel'!$B$7)
A7: =IFERROR("Target achievement: "&TEXT(('Forecast Engine'!$AT$13+'Forecast Engine'!$AU$13+'Forecast Engine'!$AV$13)/(SUMIFS('Monthly Target Upload'!$D$4:$D$15,'Monthly Target Upload'!$A$4:$A$15,'Control Panel'!$B$4)+SUMIFS('Monthly Target Upload'!$D$4:$D$15,'Monthly Target Upload'!$A$4:$A$15,'Control Panel'!$B$6)+SUMIFS('Monthly Target Upload'!$D$4:$D$15,'Monthly Target Upload'!$A$4:$A$15,'Control Panel'!$B$7)),"0.0%"),"—") | G7: ="Model accuracy (back-test): "&TEXT('Forecast Accuracy'!$B$21,"0.0%")&" · WMAPE "&TEXT('Forecast Accuracy'!$B$18,"0.0%")
A9: Brand Performance · Base 3-month forecast
A10: Brand | B10: M | C10: M+1 | D10: M+2 | E10: 3M Total | F10: % Mix
A11: Mamaearth | B11: =SUMIFS('Forecast Engine'!$AK$4:$AK$12,'Forecast Engine'!$A$4:$A$12,$A11) | C11: =SUMIFS('Forecast Engine'!$AL$4:$AL$12,'Forecast Engine'!$A$4:$A$12,$A11) | D11: =SUMIFS('Forecast Engine'!$AM$4:$AM$12,'Forecast Engine'!$A$4:$A$12,$A11) | E11: =SUM(B11:D11) | F11: =IFERROR(E11/SUM($E$11:$E$14),0)
A12: The Derma Co. | B12: =SUMIFS('Forecast Engine'!$AK$4:$AK$12,'Forecast Engine'!$A$4:$A$12,$A12) | C12: =SUMIFS('Forecast Engine'!$AL$4:$AL$12,'Forecast Engine'!$A$4:$A$12,$A12) | D12: =SUMIFS('Forecast Engine'!$AM$4:$AM$12,'Forecast Engine'!$A$4:$A$12,$A12) | E12: =SUM(B12:D12) | F12: =IFERROR(E12/SUM($E$11:$E$14),0)
A13: Aqualogica | B13: =SUMIFS('Forecast Engine'!$AK$4:$AK$12,'Forecast Engine'!$A$4:$A$12,$A13) | C13: =SUMIFS('Forecast Engine'!$AL$4:$AL$12,'Forecast Engine'!$A$4:$A$12,$A13) | D13: =SUMIFS('Forecast Engine'!$AM$4:$AM$12,'Forecast Engine'!$A$4:$A$12,$A13) | E13: =SUM(B13:D13) | F13: =IFERROR(E13/SUM($E$11:$E$14),0)
A14: BBLUNT | B14: =SUMIFS('Forecast Engine'!$AK$4:$AK$12,'Forecast Engine'!$A$4:$A$12,$A14) | C14: =SUMIFS('Forecast Engine'!$AL$4:$AL$12,'Forecast Engine'!$A$4:$A$12,$A14) | D14: =SUMIFS('Forecast Engine'!$AM$4:$AM$12,'Forecast Engine'!$A$4:$A$12,$A14) | E14: =SUM(B14:D14) | F14: =IFERROR(E14/SUM($E$11:$E$14),0)
A15: Total | B15: =SUM(B11:B14) | C15: =SUM(C11:C14) | D15: =SUM(D11:D14) | E15: =SUM(E11:E14)
A17: Quick links
A18: → Scenario Summary | E18: → Forecast Plan Article-Chain | I18: → Business_Event_Master
A19: → Event Impact Dashboard | E19: → Event Simulator | I19: → Target Distribution
A20: → Warehouse Optimization | E20: → Forecast Accuracy | I20: → AI Business Insights
A21: → Demand Planner Workbench

Sheet Control Panel
A1: CONTROL PANEL · every blue cell drives the rolling forecast
A2: 1 · Forecast Horizon (rolling)
A3: Last Actual Month (data closed through) | B3: May'26 | C3: set to the latest month present in Primary Sales History
A4: Forecast Month (M) | B4: Jun'26 | C4: first month to forecast; advance one month each cycle
A5: Business Scenario (drives 'Selected' columns) | B5: Base
A6: Forecast Month (M+1) | B6: =INDEX(Calendar!$B$3:$B$38,MATCH($B$4,Calendar!$B$3:$B$38,0)+1)
A7: Forecast Month (M+2) | B7: =INDEX(Calendar!$B$3:$B$38,MATCH($B$4,Calendar!$B$3:$B$38,0)+2)
A8: Idx · Last Actual | B8: =MATCH('Control Panel'!$B$3,Calendar!$B$3:$B$38,0)
A9: Idx · M | B9: =MATCH('Control Panel'!$B$4,Calendar!$B$3:$B$38,0)
A10: Idx · M+1 | B10: =MATCH('Control Panel'!$B$6,Calendar!$B$3:$B$38,0)
A11: Idx · M+2 | B11: =MATCH('Control Panel'!$B$7,Calendar!$B$3:$B$38,0)
A12: Month Name · M | B12: =INDEX(Calendar!$C$3:$C$38,'Control Panel'!$B$9)
A13: Month Name · M+1 | B13: =INDEX(Calendar!$C$3:$C$38,'Control Panel'!$B$10)
A14: Month Name · M+2 | B14: =INDEX(Calendar!$C$3:$C$38,'Control Panel'!$B$11)
A16: 2 · Statistical Method Weights (auto-normalised)
A17: WMA (weighted moving avg) | B17: 0.2
A18: Exponential Smoothing | B18: 0.2
A19: Linear Trend | B19: 0.15
A20: Seasonal Index | B20: 0.15
A21: CAGR | B21: 0.1
A22: Rolling Average | B22: 0.1
A23: YoY Growth | B23: 0.1
A24: Sum of method weights | B24: =SUM(B17:B23)
A26: 3 · Method Parameters
A27: Exponential Smoothing α | B27: 0.4 | C27: higher = more weight on recent months
A28: WMA weight · latest month | B28: 0.5
A29: WMA weight · 2nd month | B29: 0.3
A30: WMA weight · 3rd month | B30: 0.2
A32: 4 · AI Ensemble Blend (Statistical + Business + Drivers)
A33: Weight · Statistical | B33: 0.5
A34: Weight · Business | B34: 0.3
A35: Weight · Driver-adjusted | B35: 0.2
A36: Momentum cap (±) | B36: 0.15 | C36: limits brand-momentum driver
A38: 5 · Scenario Multipliers
A39: Base | B39: 1
A40: Optimistic | B40: 1.08
A41: Conservative | B41: 0.92
A42: Selected multiplier | B42: =IF('Control Panel'!$B$5="Optimistic",'Control Panel'!$B$40,IF('Control Panel'!$B$5="Conservative",'Control Panel'!$B$41,'Control Panel'!$B$39))
A44: 6 · Business Forecast Defaults
A45: Default business adjustment % | B45: 0.05 | C45: applied when a series has no explicit override
...

Sheet Forecast Engine
A1: FORECAST ENGINE · rolling 3-month statistical + business + AI ensemble (₹ Cr)
A2: Every value is a formula off the Control Panel. Monthly matrix (right) is pulled from Primary Sales History via SUMIFS; helper columns extract the rolling window; the 7 methods blend into Statistical → Business → AI → scenarios. See Documentation for maths.
A3: Brand | B3: Category | C3: Seas Cat | D3: M-1 | E3: M-2 | F3: M-3 | G3: M-6 | H3: M-12 | I3: Avg3 | J3: Avg6 | K3: Avg12 | L3: Momentum | M3: Trend/mo | N3: CAGR/mo | O3: Seas·M | P3: Seas·M+1 | Q3: Seas·M+2 | R3: SMLY·M | S3: SMLY·M+1 | T3: SMLY·M+2 | U3: Biz Adj % | V3: Promo1 | W3: Promo2 | X3: Promo3 | Y3: NPI1 | Z3: NPI2 | AA3: NPI3 | AB3: Stat·M | AC3: Stat·M+1 | AD3: Stat·M+2 | AE3: Biz·M | AF3: Biz·M+1 | AG3: Biz·M+2 | AH3: AI·M | AI3: AI·M+1 | AJ3: AI·M+2 | AK3: Base·M | AL3: Base·M+1 | AM3: Base·M+2 | AN3: Opt·M | AO3: Opt·M+1 | AP3: Opt·M+2 | AQ3: Cons·M | AR3: Cons·M+1 | AS3: Cons·M+2 | AT3: Sel·M | AU3: Sel·M+1 | AV3: Sel·M+2 | AW3: Apr'25 | AX3: May'25 | AY3: Jun'25 | AZ3: Jul'25 | BA3: Aug'25 | BB3: Sep'25 | BC3: Oct'25 | BD3: Nov'25 | BE3: Dec'25 | BF3: Jan'25 | BG3: Feb'25 | BH3: Mar'25 | BI3: Apr'26 | BJ3: May'26 | BK3: Jun'26 | BL3: Jul'26 | BM3: Aug'26 | BN3: Sep'26 | BO3: Oct'26 | BP3: Nov'26 | BQ3: Dec'26 | BR3: Jan'26 | BS3: Feb'26 | BT3: Mar'26
A4: Mamaearth | B4: Face | C4: Face | D4: =IFERROR(INDEX($AW4:$BT4,1,'Control Panel'!$B$8-0),0) | E4: =IFERROR(INDEX($AW4:$BT4,1,'Control Panel'!$B$8-1),0) | F4: =IFERROR(INDEX($AW4:$BT4,1,'Control Panel'!$B$8-2),0) | G4: =IFERROR(INDEX($AW4:$BT4,1,'Control Panel'!$B$8-5),0) | H4: =IFERROR(INDEX($AW4:$BT4,1,'Control Panel'!$B$8-11),0) | I4: =AVERAGE(D4,E4,F4) | J4: =(D4+E4+F4+IFERROR(INDEX($AW4:$BT4,1,'Control Panel'!$B$8-3),0)+IFERROR(INDEX($AW4:$BT4,1,'Control Panel'!$B$8-4),0)+G4)/6 | K4: =(IFERROR(INDEX($AW4:$BT4,1,'Control Panel'!$B$8-0),0)+IFERROR(INDEX($AW4:$BT4,1,'Control Panel'!$B$8-1),0)+IFERROR(INDEX($AW4:$BT4,1,'Control Panel'!$B$8-2),0)+IFERROR(INDEX($AW4:$BT4,1,'Control Panel'!$B$8-3),0)+IFERROR(INDEX($AW4:$BT4,1,'Control Panel'!$B$8-4),0)+IFERROR(INDEX($AW4:$BT4,1,'Control Panel'!$B$8-5),0)+IFERROR(INDEX($AW4:$BT4,1,'Control Panel'!$B$8-6),0)+IFERROR(INDEX($AW4:$BT4,1,'Control Panel'!$B$8-7),0)+IFERROR(INDEX($AW4:$BT4,1,'Control Panel'!$B$8-8),0)+IFERROR(INDEX($AW4:$BT4,1,'Control Panel'!$B$8-9),0)+IFERROR(INDEX($AW4:$BT4,1,'Control Panel'!$B$8-10),0)+IFERROR(INDEX($AW4:$BT4,1,'Control Panel'!$B$8-11),0))/12 | L4: =IFERROR(MAX(-'Control Panel'!$B$36,MIN('Control Panel'!$B$36,(I4-J4)/J4)),0) | M4: =(D4-G4)/5 | N4: =IFERROR(IF(H4>0,(D4/H4)^(1/12)-1,0),0) | O4: =IFERROR((IFERROR(INDEX('Seasonality Matrix'!$B$4:$M$11,MATCH($C4,'Seasonality Matrix'!$A$4:$A$11,0),MATCH('Control Panel'!$B$12,'Seasonality Matrix'!$B$3:$M$3,0)),1))/(IFERROR(AVERAGE(INDEX('Seasonality Matrix'!$B$4:$M$11,MATCH($C4,'Seasonality Matrix'!$A$4:$A$11,0),0)),1)),1) | P4: =IFERROR((IFERROR(INDEX('Seasonality Matrix'!$B$4:$M$11,MATCH($C4,'Seasonality Matrix'!$A$4:$A$11,0),MATCH('Control Panel'!$B$13,'Seasonality Matrix'!$B$3:$M$3,0)),1))/(IFERROR(AVERAGE(INDEX('Seasonality Matrix'!$B$4:$M$11,MATCH($C4,'Seasonality Matrix'!$A$4:$A$11,0),0)),1)),1) | Q4: =IFERROR((IFERROR(INDEX('Seasonality Matrix'!$B$4:$M$11,MATCH($C4,'Seasonality Matrix'!$A$4:$A$11,0),MATCH('Control Panel'!$B$14,'Seasonality Matrix'!$B$3:$M$3,0)),1))/(IFERROR(AVERAGE(INDEX('Seasonality Matrix'!$B$4:$M$11,MATCH($C4,'Seasonality Matrix'!$A$4:$A$11,0),0)),1)),1) | R4: =IFERROR(INDEX($AW4:$BT4,1,'Control Panel'!$B$9-12),0) | S4: =IFERROR(INDEX($AW4:$BT4,1,'Control Panel'!$B$10-12),0) | T4: =IFERROR(INDEX($AW4:$BT4,1,'Control Panel'!$B$11-12),0) | U4: ='Control Panel'!$B$45 | V4: =IFERROR(SUMIFS('Promotion Calendar'!$G$4:$G$12,'Promotion Calendar'!$A$4:$A$12,$A4,'Promotion Calendar'!$B$4:$B$12,$B4,'Promotion Calendar'!$C$4:$C$12,'Control Panel'!$B$4),0) | W4: =IFERROR(SUMIFS('Promotion Calendar'!$G$4:$G$12,'Promotion Calendar'!$A$4:$A$12,$A4,'Promotion Calendar'!$B$4:$B$12,$B4,'Promotion Calendar'!$C$4:$C$12,'Control Panel'!$B$6),0) | X4: =IFERROR(SUMIFS('Promotion Calendar'!$G$4:$G$12,'Promotion Calendar'!$A$4:$A$12,$A4,'Promotion Calendar'!$B$4:$B$12,$B4,'Promotion Calendar'!$C$4:$C$12,'Control Panel'!$B$7),0) | Y4: =IFERROR(SUMIFS('NPI & EPD Planning'!$I$4:$I$10,'NPI & EPD Planning'!$A$4:$A$10,$A4,'NPI & EPD Planning'!$B$4:$B$10,$B4,'NPI & EPD Planning'!$D$4:$D$10,'Control Panel'!$B$4),0) | Z4: =IFERROR(SUMIFS('NPI & EPD Planning'!$I$4:$I$10,'NPI & EPD Planning'!$A$4:$A$10,$A4,'NPI & EPD Planning'!$B$4:$B$10,$B4,'NPI & EPD Planning'!$D$4:$D$10,'Control Panel'!$B$6),0) | AA4: =IFERROR(SUMIFS('NPI & EPD Planning'!$I$4:$I$10,'NPI & EPD Planning'!$A$4:$A$10,$A4,'NPI & EPD Planning'!$B$4:$B$10,$B4,'NPI & EPD Planning'!$D$4:$D$10,'Control Panel'!$B$7),0) | AB4: =IFERROR(('Control Panel'!$B$17*(('Control Panel'!$B$28*D4+'Control Panel'!$B$29*E4+'Control Panel'!$B$30*F4)*O4)+'Control Panel'!$B$18*((('Control Panel'!$B$27*(1-'Control Panel'!$B$27)^0*IFERROR(INDEX($AW4:$BT4,1,'Control Panel'!$B$8-0),0)+'Control Panel'!$B$27*(1-'Control Panel'!$B$27)^1*IFERROR(INDEX($AW4:$BT4,1,'Control Panel'!$B$8-1),0)+'Control Panel'!$B$27*(1-'Control Panel'!$B$27)^2*IFERROR(INDEX($AW4:$BT4,1,'Control Panel'!$B$8-2),0)+'Control Panel'!$B$27*(1-'Control Panel'!$B$27)^3*IFERROR(INDEX($AW4:$BT4,1,'Control Panel'!$B$8-3),0)+'Control Panel'!$B$27*(1-'Control Panel'!$B$27)^4*IFERROR(INDEX($AW4:$BT4,1,'Control Panel'!$B$8-4),0)+'Control Panel'!$B$27*(1-'Control Panel'!$B$27)^5*IFERROR(INDEX($AW4:$BT4,1,'Control Panel'!$B$8-5),0))/(1-(1-'Control Panel'!$B$27)^6))*O4)+'Control Panel'!$B$19*((D4+M4*1)*O4)+'Control Panel'!$B$20*(K4*O4)+'Control Panel'!$B$21*(D4*(1+N4)^1*O4)+'Control Panel'!$B$22*(I4*O4)+'Control Panel'!$B$23*(R4*(1+IFERROR(D4/H4-1,0))))/'Control Panel'!$B$24,0) | AC4: =IFERROR(('Control Panel'!$B$17*(('Control Panel'!$B$28*D4+'Control Panel'!$B$29*E4+'Control Panel'!$B$30*F4)*P4)+'Control Panel'!$B$18*((('Control Panel'!$B$27*(1-'Control Panel'!$B$27)^0*IFERROR(INDEX($AW4:$BT4,1,'Control Panel'!$B$8-0),0)+'Control Panel'!$B$27*(1-'Control Panel'!$B$27)^1*IFERROR(INDEX($AW4:$BT4,1,'Control Panel'!$B$8-1),0)+'Control Panel'!$B$27*(1-'Control Panel'!$B$27)^2*IFERROR(INDEX($AW4:$BT4,1,'Control Panel'!$B$8-2),0)+'Control Panel'!$B$27*(1-'Control Panel'!$B$27)^3*IFERROR(INDEX($AW4:$BT4,1,'Control Panel'!$B$8-3),0)+'Control Panel'!$B$27*(1-'Control Panel'!$B$27)^4*IFERROR(INDEX($AW4:$BT4,1,'Control Panel'!$B$8-4),0)+'Control Panel'!$B$27*(1-'Control Panel'!$B$27)^5*IFERROR(INDEX($AW4:$BT4,1,'Control Panel'!$B$8-5),0))/(1-(1-'Control Panel'!$B$27)^6))*P4)+'Control Panel'!$B$19*((D4+M4*2)*P4)+'Control Panel'!$B$20*(K4*P4)+'Control Panel'!$B$21*(D4*(1+N4)^2*P4)+'Control Panel'!$B$22*(I4*P4)+'Control Panel'!$B$23*(S4*(1+IFERROR(D4/H4-1,0))))/'Control Panel'!$B$24,0) | AD4: =IFERROR(('Control Panel'!$B$17*(('Control Panel'!$B$28*D4+'Control Panel'!$B$29*E4+'Control Panel'!$B$30*F4)*Q4)+'Control Panel'!$B$18*((('Control Panel'!$B$27*(1-'Control Panel'!$B$27)^0*IFERROR(INDEX($AW4:$BT4,1,'Control Panel'!$B$8-0),0)+'Control Panel'!$B$27*(1-'Control Panel'!$B$27)^1*IFERROR(INDEX($AW4:$BT4,1,'Control Panel'!$B$8-1),0)+'Control Panel'!$B$27*(1-'Control Panel'!$B$27)^2*IFERROR(INDEX($AW4:$BT4,1,'Control Panel'!$B$8-2),0)+'Control Panel'!$B$27*(1-'Control Panel'!$B$27)^3*IFERROR(INDEX($AW4:$BT4,1,'Control Panel'!$B$8-3),0)+'Control Panel'!$B$27*(1-'Control Panel'!$B$27)^4*IFERROR(INDEX($AW4:$BT4,1,'Control Panel'!$B$8-4),0)+'Control Panel'!$B$27*(1-'Control Panel'!$B$27)^5*IFERROR(INDEX($AW4:$BT4,1,'Control Panel'!$B$8-5),0))/(1-(1-'Control Panel'!$B$27)^6))*Q4)+'Control Panel'!$B$19*((D4+M4*3)*Q4)+'Control Panel'!$B$20*(K4*Q4)+'Control Panel'!$B$21*(D4*(1+N4)^3*Q4)+'Control Panel'!$B$22*(I4*Q4)+'Control Panel'!$B$23*(T4*(1+IFERROR(D4/H4-1,0))))/'Control Panel'!$B$24,0) | AE4: =MAX(0,AB4*(1+U4+V4)) | AF4: =MAX(0,AC4*(1+U4+W4)) | AG4: =MAX(0,AD4*(1+U4+X4)) | AH4: =IFERROR(('Control Panel'!$B$33*AB4+'Control Panel'!$B$34*AE4+'Control Panel'!$B$35*(AB4*(1+L4+V4)))/('Control Panel'!$B$33+'Control Panel'!$B$34+'Control Panel'!$B$35),0) | AI4: =IFERROR(('Control Panel'!$B$33*AC4+'Control Panel'!$B$34*AF4+'Control Panel'!$B$35*(AC4*(1+L4+W4)))/('Control Panel'!$B$33+'Control Panel'!$B$34+'Control Panel'!$B$35),0) | AJ4: =IFERROR(('Control Panel'!$B$33*AD4+'Control Panel'!$B$34*AG4+'Control Panel'!$B$35*(AD4*(1+L4+X4)))/('Control Panel'!$B$33+'Control Panel'!$B$34+'Control Panel'!$B$35),0) | AK4: =AH4*'Control Panel'!$B$39+Y4 | AL4: =AI4*'Control Panel'!$B$39+Z4 | AM4: =AJ4*'Control Panel'!$B$39+AA4 | AN4: =AH4*'Control Panel'!$B$40+Y4 | AO4: =AI4*'Control Panel'!$B$40+Z4 | AP4: =AJ4*'Control Panel'!$B$40+AA4 | AQ4: =AH4*'Control Panel'!$B$41+Y4 | AR4: =AI4*'Control Panel'!$B$41+Z4 | AS4: =AJ4*'Control Panel'!$B$41+AA4 | AT4: =AH4*'Control Panel'!$B$42+Y4 | AU4: =AI4*'Control Panel'!$B$42+Z4 | AV4: =AJ4*'Control Panel'!$B$42+AA4 | AW4: =SUMIFS('Primary Sales History'!$C$4:$C$33,'Primary Sales History'!$A$4:$A$33,$A4,'Primary Sales History'!$B$4:$B$33,$B4) | AX4: =SUMIFS('Primary Sales History'!$D$4:$D$33,'Primary Sales History'!$A$4:$A$33,$A4,'Primary Sales History'!$B$4:$B$33,$B4) | AY4: =SUMIFS('Primary Sales History'!$E$4:$E$33,'Primary Sales History'!$A$4:$A$33,$A4,'Primary Sales History'!$B$4:$B$33,$B4) | AZ4: =SUMIFS('Primary Sales History'!$F$4:$F$33,'Primary Sales History'!$A$4:$A$33,$A4,'Primary Sales History'!$B$4:$B$33,$B4) | BA4: =SUMIFS('Primary Sales History'!$G$4:$G$33,'Primary Sales History'!$A$4:$A$33,$A4,'Primary Sales History'!$B$4:$B$33,$B4) | BB4: =SUMIFS('Primary Sales History'!$H$4:$H$33,'Primary Sales History'!$A$4:$A$33,$A4,'Primary Sales History'!$B$4:$B$33,$B4) | BC4: =SUMIFS('Primary Sales History'!$I$4:$I$33,'Primary Sales History'!$A$4:$A$33,$A4,'Primary Sales History'!$B$4:$B$33,$B4) | BD4: =SUMIFS('Primary Sales History'!$J$4:$J$33,'Primary Sales History'!$A$4:$A$33,$A4,'Primary Sales History'!$B$4:$B$33,$B4) | BE4: =SUMIFS('Primary Sales History'!$K$4:$K$33,'Primary Sales History'!$A$4:$A$33,$A4,'Primary Sales History'!$B$4:$B$33,$B4) | BF4: =SUMIFS('Primary Sales History'!$L$4:$L$33,'Primary Sales History'!$A$4:$A$33,$A4,'Primary Sales History'!$B$4:$B$33,$B4) | BG4: =SUMIFS('Primary Sales History'!$M$4:$M$33,'Primary Sales History'!$A$4:$A$33,$A4,'Primary Sales History'!$B$4:$B$33,$B4) | BH4: =SUMIFS('Primary Sales History'!$N$4:$N$33,'Primary Sales History'!$A$4:$A$33,$A4,'Primary Sales History'!$B$4:$B$33,$B4) | BI4: =SUMIFS('Primary Sales History'!$O$4:$O$33,'Primary Sales History'!$A$4:$A$33,$A4,'Primary Sales History'!$B$4:$B$33,$B4) | BJ4: =SUMIFS('Primary Sales History'!$P$4:$P$33,'Primary Sales History'!$A$4:$A$33,$A4,'Primary Sales History'!$B$4:$B$33,$B4) | BK4: 0 | BL4: 0 | BM4: 0 | BN4: 0 | BO4: 0 | BP4: 0 | BQ4: 0 | BR4: 0 | BS4: 0 | BT4: 0
A5: Mamaearth | B5: Hair | C5: Hair | D5: =IFERROR(INDEX($AW5:$BT5,1,'Control Panel'!$B$8-0),0) | E5: =IFERROR(INDEX($AW5:$BT5,1,'Control Panel'!$B$8-1),0) | F5: =IFERROR(INDEX($AW5:$BT5,1,'Control Panel'!$B$8-2),0) | G5: =IFERROR(INDEX($AW5:$BT5,1,'Control Panel'!$B$8-5),0) | H5: =IFERROR(INDEX($AW5:$BT5,1,'Control Panel'!$B$8-11),0) | I5: =AVERAGE(D5,E5,F5) | J5: =(D5+E5+F5+IFERROR(INDEX($AW5:$BT5,1,'Control Panel'!$B$8-3),0)+IFERROR(INDEX($AW5:$BT5,1,'Control Panel'!$B$8-4),0)+G5)/6 | K5: =(IFERROR(INDEX($AW5:$BT5,1,'Control Panel'!$B$8-0),0)+IFERROR(INDEX($AW5:$BT5,1,'Control Panel'!$B$8-1),0)+IFERROR(INDEX($AW5:$BT5,1,'Control Panel'!$B$8-2),0)+IFERROR(INDEX($AW5:$BT5,1,'Control Panel'!$B$8-3),0)+IFERROR(INDEX($AW5:$BT5,1,'Control Panel'!$B$8-4),0)+IFERROR(INDEX($AW5:$BT5,1,'Control Panel'!$B$8-5),0)+IFERROR(INDEX($AW5:$BT5,1,'Control Panel'!$B$8-6),0)+IFERROR(INDEX($AW5:$BT5,1,'Control Panel'!$B$8-7),0)+IFERROR(INDEX($AW5:$BT5,1,'Control Panel'!$B$8-8),0)+IFERROR(INDEX($AW5:$BT5,1,'Control Panel'!$B$8-9),0)+IFERROR(INDEX($AW5:$BT5,1,'Control Panel'!$B$8-10),0)+IFERROR(INDEX($AW5:$BT5,1,'Control Panel'!$B$8-11),0))/12 | L5: =IFERROR(MAX(-'Control Panel'!$B$36,MIN('Control Panel'!$B$36,(I5-J5)/J5)),0) | M5: =(D5-G5)/5 | N5: =IFERROR(IF(H5>0,(D5/H5)^(1/12)-1,0),0) | O5: =IFERROR((IFERROR(INDEX('Seasonality Matrix'!$B$4:$M$11,MATCH($C5,'Seasonality Matrix'!$A$4:$A$11,0),MATCH('Control Panel'!$B$12,'Seasonality Matrix'!$B$3:$M$3,0)),1))/(IFERROR(AVERAGE(INDEX('Seasonality Matrix'!$B$4:$M$11,MATCH($C5,'Seasonality Matrix'!$A$4:$A$11,0),0)),1)),1) | P5: =IFERROR((IFERROR(INDEX('Seasonality Matrix'!$B$4:$M$11,MATCH($C5,'Seasonality Matrix'!$A$4:$A$11,0),MATCH('Control Panel'!$B$13,'Seasonality Matrix'!$B$3:$M$3,0)),1))/(IFERROR(AVERAGE(INDEX('Seasonality Matrix'!$B$4:$M$11,MATCH($C5,'Seasonality Matrix'!$A$4:$A$11,0),0)),1)),1) | Q5: =IFERROR((IFERROR(INDEX('Seasonality Matrix'!$B$4:$M$11,MATCH($C5,'Seasonality Matrix'!$A$4:$A$11,0),MATCH('Control Panel'!$B$14,'Seasonality Matrix'!$B$3:$M$3,0)),1))/(IFERROR(AVERAGE(INDEX('Seasonality Matrix'!$B$4:$M$11,MATCH($C5,'Seasonality Matrix'!$A$4:$A$11,0),0)),1)),1) | R5: =IFERROR(INDEX($AW5:$BT5,1,'Control Panel'!$B$9-12),0) | S5: =IFERROR(INDEX($AW5:$BT5,1,'Control Panel'!$B$10-12),0) | T5: =IFERROR(INDEX($AW5:$BT5,1,'Control Panel'!$B$11-12),0) | U5: ='Control Panel'!$B$45 | V5: =IFERROR(SUMIFS('Promotion Calendar'!$G$4:$G$12,'Promotion Calendar'!$A$4:$A$12,$A5,'Promotion Calendar'!$B$4:$B$12,$B5,'Promotion Calendar'!$C$4:$C$12,'Control Panel'!$B$4),0) | W5: =IFERROR(SUMIFS('Promotion Calendar'!$G$4:$G$12,'Promotion Calendar'!$A$4:$A$12,$A5,'Promotion Calendar'!$B$4:$B$12,$B5,'Promotion Calendar'!$C$4:$C$12,'Control Panel'!$B$6),0) | X5: =IFERROR(SUMIFS('Promotion Calendar'!$G$4:$G$12,'Promotion Calendar'!$A$4:$A$12,$A5,'Promotion Calendar'!$B$4:$B$12,$B5,'Promotion Calendar'!$C$4:$C$12,'Control Panel'!$B$7),0) | Y5: =IFERROR(SUMIFS('NPI & EPD Planning'!$I$4:$I$10,'NPI & EPD Planning'!$A$4:$A$10,$A5,'NPI & EPD Planning'!$B$4:$B$10,$B5,'NPI & EPD Planning'!$D$4:$D$10,'Control Panel'!$B$4),0) | Z5: =IFERROR(SUMIFS('NPI & EPD Planning'!$I$4:$I$10,'NPI & EPD Planning'!$A$4:$A$10,$A5,'NPI & EPD Planning'!$B$4:$B$10,$B5,'NPI & EPD Planning'!$D$4:$D$10,'Control Panel'!$B$6),0) | AA5: =IFERROR(SUMIFS('NPI & EPD Planning'!$I$4:$I$10,'NPI & EPD Planning'!$A$4:$A$10,$A5,'NPI & EPD Planning'!$B$4:$B$10,$B5,'NPI & EPD Planning'!$D$4:$D$10,'Control Panel'!$B$7),0) | AB5: =IFERROR(('Control Panel'!$B$17*(('Control Panel'!$B$28*D5+'Control Panel'!$B$29*E5+'Control Panel'!$B$30*F5)*O5)+'Control Panel'!$B$18*((('Control Panel'!$B$27*(1-'Control Panel'!$B$27)^0*IFERROR(INDEX($AW5:$BT5,1,'Control Panel'!$B$8-0),0)+'Control Panel'!$B$27*(1-'Control Panel'!$B$27)^1*IFERROR(INDEX($AW5:$BT5,1,'Control Panel'!$B$8-1),0)+'Control Panel'!$B$27*(1-'Control Panel'!$B$27)^2*IFERROR(INDEX($AW5:$BT5,1,'Control Panel'!$B$8-2),0)+'Control Panel'!$B$27*(1-'Control Panel'!$B$27)^3*IFERROR(INDEX($AW5:$BT5,1,'Control Panel'!$B$8-3),0)+'Control Panel'!$B$27*(1-'Control Panel'!$B$27)^4*IFERROR(INDEX($AW5:$BT5,1,'Control Panel'!$B$8-4),0)+'Control Panel'!$B$27*(1-'Control Panel'!$B$27)^5*IFERROR(INDEX($AW5:$BT5,1,'Control Panel'!$B$8-5),0))/(1-(1-'Control Panel'!$B$27)^6))*O5)+'Control Panel'!$B$19*((D5+M5*1)*O5)+'Control Panel'!$B$20*(K5*O5)+'Control Panel'!$B$21*(D5*(1+N5)^1*O5)+'Control Panel'!$B$22*(I5*O5)+'Control Panel'!$B$23*(R5*(1+IFERROR(D5/H5-1,0))))/'Control Panel'!$B$24,0) | AC5: =IFERROR(('Control Panel'!$B$17*(('Control Panel'!$B$28*D5+'Control Panel'!$B$29*E5+'Control Panel'!$B$30*F5)*P5)+'Control Panel'!$B$18*((('Control Panel'!$B$27*(1-'Control Panel'!$B$27)^0*IFERROR(INDEX($AW5:$BT5,1,'Control Panel'!$B$8-0),0)+'Control Panel'!$B$27*(1-'Control Panel'!$B$27)^1*IFERROR(INDEX($AW5:$BT5,1,'Control Panel'!$B$8-1),0)+'Control Panel'!$B$27*(1-'Control Panel'!$B$27)^2*IFERROR(INDEX($AW5:$BT5,1,'Control Panel'!$B$8-2),0)+'Control Panel'!$B$27*(1-'Control Panel'!$B$27)^3*IFERROR(INDEX($AW5:$BT5,1,'Control Panel'!$B$8-3),0)+'Control Panel'!$B$27*(1-'Control Panel'!$B$27)^4*IFERROR(INDEX($AW5:$BT5,1,'Control Panel'!$B$8-4),0)+'Control Panel'!$B$27*(1-'Control Panel'!$B$27)^5*IFERROR(INDEX($AW5:$BT5,1,'Control Panel'!$B$8-5),0))/(1-(1-'Control Panel'!$B$27)^6))*P5)+'Control Panel'!$B$19*((D5+M5*2)*P5)+'Control Panel'!$B$20*(K5*P5)+'Control Panel'!$B$21*(D5*(1+N5)^2*P5)+'Control Panel'!$B$22*(I5*P5)+'Control Panel'!$B$23*(S5*(1+IFERROR(D5/H5-1,0))))/'Control Panel'!$B$24,0) | AD5: =IFERROR(('Control Panel'!$B$17*(('Control Panel'!$B$28*D5+'Control Panel'!$B$29*E5+'Control Panel'!$B$30*F5)*Q5)+'Control Panel'!$B$18*((('Control Panel'!$B$27*(1-'Control Panel'!$B$27)^0*IFERROR(INDEX($AW5:$BT5,1,'Control Panel'!$B$8-0),0)+'Control Panel'!$B$27*(1-'Control Panel'!$B$27)^1*IFERROR(INDEX($AW5:$BT5,1,'Control Panel'!$B$8-1),0)+'Control Panel'!$B$27*(1-'Control Panel'!$B$27)^2*IFERROR(INDEX($AW5:$BT5,1,'Control Panel'!$B$8-2),0)+'Control Panel'!$B$27*(1-'Control Panel'!$B$27)^3*IFERROR(INDEX($AW5:$BT5,1,'Control Panel'!$B$8-3),0)+'Control Panel'!$B$27*(1-'Control Panel'!$B$27)^4*IFERROR(INDEX($AW5:$BT5,1,'Control Panel'!$B$8-4),0)+'Control Panel'!$B$27*(1-'Control Panel'!$B$27)^5*IFERROR(INDEX($AW5:$BT5,1,'Control Panel'!$B$8-5),0))/(1-(1-'Control Panel'!$B$27)^6))*Q5)+'Control Panel'!$B$19*((D5+M5*3)*Q5)+'Control Panel'!$B$20*(K5*Q5)+'Control Panel'!$B$21*(D5*(1+N5)^3*Q5)+'Control Panel'!$B$22*(I5*Q5)+'Control Panel'!$B$23*(T5*(1+IFERROR(D5/H5-1,0))))/'Control Panel'!$B$24,0) | AE5: =MAX(0,AB5*(1+U5+V5)) | AF5: =MAX(0,AC5*(1+U5+W5)) | AG5: =MAX(0,AD5*(1+U5+X5)) | AH5: =IFERROR(('Control Panel'!$B$33*AB5+'Control Panel'!$B$34*AE5+'Control Panel'!$B$35*(AB5*(1+L5+V5)))/('Control Panel'!$B$33+'Control Panel'!$B$34+'Control Panel'!$B$35),0) | AI5: =IFERROR(('Control Panel'!$B$33*AC5+'Control Panel'!$B$34*AF5+'Control Panel'!$B$35*(AC5*(1+L5+W5)))/('Control Panel'!$B$33+'Control Panel'!$B$34+'Control Panel'!$B$35),0) | AJ5: =IFERROR(('Control Panel'!$B$33*AD5+'Control Panel'!$B$34*AG5+'Control Panel'!$B$35*(AD5*(1+L5+X5)))/('Control Panel'!$B$33+'Control Panel'!$B$34+'Control Panel'!$B$35),0) | AK5: =AH5*'Control Panel'!$B$39+Y5 | AL5: =AI5*'Control Panel'!$B$39+Z5 | AM5: =AJ5*'Control Panel'!$B$39+AA5 | AN5: =AH5*'Control Panel'!$B$40+Y5 | AO5: =AI5*'Control Panel'!$B$40+Z5 | AP5: =AJ5*'Control Panel'!$B$40+AA5 | AQ5: =AH5*'Control Panel'!$B$41+Y5 | AR5: =AI5*'Control Panel'!$B$41+Z5 | AS5: =AJ5*'Control Panel'!$B$41+AA5 | AT5: =AH5*'Control Panel'!$B$42+Y5 | AU5: =AI5*'Control Panel'!$B$42+Z5 | AV5: =AJ5*'Control Panel'!$B$42+AA5 | AW5: =SUMIFS('Primary Sales History'!$C$4:$C$33,'Primary Sales History'!$A$4:$A$33,$A5,'Primary Sales History'!$B$4:$B$33,$B5) | AX5: =SUMIFS('Primary Sales History'!$D$4:$D$33,'Primary Sales History'!$A$4:$A$33,$A5,'Primary Sales History'!$B$4:$B$33,$B5) | AY5: =SUMIFS('Primary Sales History'!$E$4:$E$33,'Primary Sales History'!$A$4:$A$33,$A5,'Primary Sales History'!$B$4:$B$33,$B5) | AZ5: =SUMIFS('Primary Sales History'!$F$4:$F$33,'Primary Sales History'!$A$4:$A$33,$A5,'Primary Sales History'!$B$4:$B$33,$B5) | BA5: =SUMIFS('Primary Sales History'!$G$4:$G$33,'Primary Sales History'!$A$4:$A$33,$A5,'Primary Sales History'!$B$4:$B$33,$B5) | BB5: =SUMIFS('Primary Sales History'!$H$4:$H$33,'Primary Sales History'!$A$4:$A$33,$A5,'Primary Sales History'!$B$4:$B$33,$B5) | BC5: =SUMIFS('Primary Sales History'!$I$4:$I$33,'Primary Sales History'!$A$4:$A$33,$A5,'Primary Sales History'!$B$4:$B$33,$B5) | BD5: =SUMIFS('Primary Sales History'!$J$4:$J$33,'Primary Sales History'!$A$4:$A$33,$A5,'Primary Sales History'!$B$4:$B$33,$B5) | BE5: =SUMIFS('Primary Sales History'!$K$4:$K$33,'Primary Sales History'!$A$4:$A$33,$A5,'Primary Sales History'!$B$4:$B$33,$B5) | BF5: =SUMIFS('Primary Sales History'!$L$4:$L$33,'Primary Sales History'!$A$4:$A$33,$A5,'Primary Sales History'!$B$4:$B$33,$B5) | BG5: =SUMIFS('Primary Sales History'!$M$4:$M$33,'Primary Sales History'!$A$4:$A$33,$A5,'Primary Sales History'!$B$4:$B$33,$B5) | BH5: =SUMIFS('Primary Sales History'!$N$4:$N$33,'Primary Sales History'!$A$4:$A$33,$A5,'Primary Sales History'!$B$4:$B$33,$B5) | BI5: =SUMIFS('Primary Sales History'!$O$4:$O$33,'Primary Sales History'!$A$4:$A$33,$A5,'Primary Sales History'!$B$4:$B$33,$B5) | BJ5: =SUMIFS('Primary Sales History'!$P$4:$P$33,'Primary Sales History'!$A$4:$A$33,$A5,'Primary Sales History'!$B$4:$B$33,$B5) | BK5: 0 | BL5: 0 | BM5: 0 | BN5: 0 | BO5: 0 | BP5: 0 | BQ5: 0 | BR5: 0 | BS5: 0 | BT5: 0
A6: The Derma Co. | B6: Face | C6: Face | D6: =IFERROR(INDEX($AW6:$BT6,1,'Control Panel'!$B$8-0),0) | E6: =IFERROR(INDEX($AW6:$BT6,1,'Control Panel'!$B$8-1),0) | F6: =IFERROR(INDEX($AW6:$BT6,1,'Control Panel'!$B$8-2),0) | G6: =IFERROR(INDEX($AW6:$BT6,1,'Control Panel'!$B$8-5),0) | H6: =IFERROR(INDEX($AW6:$BT6,1,'Control Panel'!$B$8-11),0) | I6: =AVERAGE(D6,E6,F6) | J6: =(D6+E6+F6+IFERROR(INDEX($AW6:$BT6,1,'Control Panel'!$B$8-3),0)+IFERROR(INDEX($AW6:$BT6,1,'Control Panel'!$B$8-4),0)+G6)/6 | K6: =(IFERROR(INDEX($AW6:$BT6,1,'Control Panel'!$B$8-0),0)+IFERROR(INDEX($AW6:$BT6,1,'Control Panel'!$B$8-1),0)+IFERROR(INDEX($AW6:$BT6,1,'Control Panel'!$B$8-2),0)+IFERROR(INDEX($AW6:$BT6,1,'Control Panel'!$B$8-3),0)+IFERROR(INDEX($AW6:$BT6,1,'Control Panel'!$B$8-4),0)+IFERROR(INDEX($AW6:$BT6,1,'Control Panel'!$B$8-5),0)+IFERROR(INDEX($AW6:$BT6,1,'Control Panel'!$B$8-6),0)+IFERROR(INDEX($AW6:$BT6,1,'Control Panel'!$B$8-7),0)+IFERROR(INDEX($AW6:$BT6,1,'Control Panel'!$B$8-8),0)+IFERROR(INDEX($AW6:$BT6,1,'Control Panel'!$B$8-9),0)+IFERROR(INDEX($AW6:$BT6,1,'Control Panel'!$B$8-10),0)+IFERROR(INDEX($AW6:$BT6,1,'Control Panel'!$B$8-11),0))/12 | L6: =IFERROR(MAX(-'Control Panel'!$B$36,MIN('Control Panel'!$B$36,(I6-J6)/J6)),0) | M6: =(D6-G6)/5 | N6: =IFERROR(IF(H6>0,(D6/H6)^(1/12)-1,0),0) | O6: =IFERROR((IFERROR(INDEX('Seasonality Matrix'!$B$4:$M$11,MATCH($C6,'Seasonality Matrix'!$A$4:$A$11,0),MATCH('Control Panel'!$B$12,'Seasonality Matrix'!$B$3:$M$3,0)),1))/(IFERROR(AVERAGE(INDEX('Seasonality Matrix'!$B$4:$M$11,MATCH($C6,'Seasonality Matrix'!$A$4:$A$11,0),0)),1)),1) | P6: =IFERROR((IFERROR(INDEX('Seasonality Matrix'!$B$4:$M$11,MATCH($C6,'Seasonality Matrix'!$A$4:$A$11,0),MATCH('Control Panel'!$B$13,'Seasonality Matrix'!$B$3:$M$3,0)),1))/(IFERROR(AVERAGE(INDEX('Seasonality Matrix'!$B$4:$M$11,MATCH($C6,'Seasonality Matrix'!$A$4:$A$11,0),0)),1)),1) | Q6: =IFERROR((IFERROR(INDEX('Seasonality Matrix'!$B$4:$M$11,MATCH($C6,'Seasonality Matrix'!$A$4:$A$11,0),MATCH('Control Panel'!$B$14,'Seasonality Matrix'!$B$3:$M$3,0)),1))/(IFERROR(AVERAGE(INDEX('Seasonality Matrix'!$B$4:$M$11,MATCH($C6,'Seasonality Matrix'!$A$4:$A$11,0),0)),1)),1) | R6: =IFERROR(INDEX($AW6:$BT6,1,'Control Panel'!$B$9-12),0) | S6: =IFERROR(INDEX($AW6:$BT6,1,'Control Panel'!$B$10-12),0) | T6: =IFERROR(INDEX($AW6:$BT6,1,'Control Panel'!$B$11-12),0) | U6: ='Control Panel'!$B$45 | V6: =IFERROR(SUMIFS('Promotion Calendar'!$G$4:$G$12,'Promotion Calendar'!$A$4:$A$12,$A6,'Promotion Calendar'!$B$4:$B$12,$B6,'Promotion Calendar'!$C$4:$C$12,'Control Panel'!$B$4),0) | W6: =IFERROR(SUMIFS('Promotion Calendar'!$G$4:$G$12,'Promotion Calendar'!$A$4:$A$12,$A6,'Promotion Calendar'!$B$4:$B$12,$B6,'Promotion Calendar'!$C$4:$C$12,'Control Panel'!$B$6),0) | X6: =IFERROR(SUMIFS('Promotion Calendar'!$G$4:$G$12,'Promotion Calendar'!$A$4:$A$12,$A6,'Promotion Calendar'!$B$4:$B$12,$B6,'Promotion Calendar'!$C$4:$C$12,'Control Panel'!$B$7),0) | Y6: =IFERROR(SUMIFS('NPI & EPD Planning'!$I$4:$I$10,'NPI & EPD Planning'!$A$4:$A$10,$A6,'NPI & EPD Planning'!$B$4:$B$10,$B6,'NPI & EPD Planning'!$D$4:$D$10,'Control Panel'!$B$4),0) | Z6: =IFERROR(SUMIFS('NPI & EPD Planning'!$I$4:$I$10,'NPI & EPD Planning'!$A$4:$A$10,$A6,'NPI & EPD Planning'!$B$4:$B$10,$B6,'NPI & EPD Planning'!$D$4:$D$10,'Control Panel'!$B$6),0) | AA6: =IFERROR(SUMIFS('NPI & EPD Planning'!$I$4:$I$10,'NPI & EPD Planning'!$A$4:$A$10,$A6,'NPI & EPD Planning'!$B$4:$B$10,$B6,'NPI & EPD Planning'!$D$4:$D$10,'Control Panel'!$B$7),0) | AB6: =IFERROR(('Control Panel'!$B$17*(('Control Panel'!$B$28*D6+'Control Panel'!$B$29*E6+'Control Panel'!$B$30*F6)*O6)+'Control Panel'!$B$18*((('Control Panel'!$B$27*(1-'Control Panel'!$B$27)^0*IFERROR(INDEX($AW6:$BT6,1,'Control Panel'!$B$8-0),0)+'Control Panel'!$B$27*(1-'Control Panel'!$B$27)^1*IFERROR(INDEX($AW6:$BT6,1,'Control Panel'!$B$8-1),0)+'Control Panel'!$B$27*(1-'Control Panel'!$B$27)^2*IFERROR(INDEX($AW6:$BT6,1,'Control Panel'!$B$8-2),0)+'Control Panel'!$B$27*(1-'Control Panel'!$B$27)^3*IFERROR(INDEX($AW6:$BT6,1,'Control Panel'!$B$8-3),0)+'Control Panel'!$B$27*(1-'Control Panel'!$B$27)^4*IFERROR(INDEX($AW6:$BT6,1,'Control Panel'!$B$8-4),0)+'Control Panel'!$B$27*(1-'Control Panel'!$B$27)^5*IFERROR(INDEX($AW6:$BT6,1,'Control Panel'!$B$8-5),0))/(1-(1-'Control Panel'!$B$27)^6))*O6)+'Control Panel'!$B$19*((D6+M6*1)*O6)+'Control Panel'!$B$20*(K6*O6)+'Control Panel'!$B$21*(D6*(1+N6)^1*O6)+'Control Panel'!$B$22*(I6*O6)+'Control Panel'!$B$23*(R6*(1+IFERROR(D6/H6-1,0))))/'Control Panel'!$B$24,0) | AC6: =IFERROR(('Control Panel'!$B$17*(('Control Panel'!$B$28*D6+'Control Panel'!$B$29*E6+'Control Panel'!$B$30*F6)*P6)+'Control Panel'!$B$18*((('Control Panel'!$B$27*(1-'Control Panel'!$B$27)^0*IFERROR(INDEX($AW6:$BT6,1,'Control Panel'!$B$8-0),0)+'Control Panel'!$B$27*(1-'Control Panel'!$B$27)^1*IFERROR(INDEX($AW6:$BT6,1,'Control Panel'!$B$8-1),0)+'Control Panel'!$B$27*(1-'Control Panel'!$B$27)^2*IFERROR(INDEX($AW6:$BT6,1,'Control Panel'!$B$8-2),0)+'Control Panel'!$B$27*(1-'Control Panel'!$B$27)^3*IFERROR(INDEX($AW6:$BT6,1,'Control Panel'!$B$8-3),0)+'Control Panel'!$B$27*(1-'Control Panel'!$B$27)^4*IFERROR(INDEX($AW6:$BT6,1,'Control Panel'!$B$8-4),0)+'Control Panel'!$B$27*(1-'Control Panel'!$B$27)^5*IFERROR(INDEX($AW6:$BT6,1,'Control Panel'!$B$8-5),0))/(1-(1-'Control Panel'!$B$27)^6))*P6)+'Control Panel'!$B$19*((D6+M6*2)*P6)+'Control Panel'!$B$20*(K6*P6)+'Control Panel'!$B$21*(D6*(1+N6)^2*P6)+'Control Panel'!$B$22*(I6*P6)+'Control Panel'!$B$23*(S6*(1+IFERROR(D6/H6-1,0))))/'Control Panel'!$B$24,0) | AD6: =IFERROR(('Control Panel'!$B$17*(('Control Panel'!$B$28*D6+'Control Panel'!$B$29*E6+'Control Panel'!$B$30*F6)*Q6)+'Control Panel'!$B$18*((('Control Panel'!$B$27*(1-'Control Panel'!$B$27)^0*IFERROR(INDEX($AW6:$BT6,1,'Control Panel'!$B$8-0),0)+'Control Panel'!$B$27*(1-'Control Panel'!$B$27)^1*IFERROR(INDEX($AW6:$BT6,1,'Control Panel'!$B$8-1),0)+'Control Panel'!$B$27*(1-'Control Panel'!$B$27)^2*IFERROR(INDEX($AW6:$BT6,1,'Control Panel'!$B$8-2),0)+'Control Panel'!$B$27*(1-'Control Panel'!$B$27)^3*IFERROR(INDEX($AW6:$BT6,1,'Control Panel'!$B$8-3),0)+'Control Panel'!$B$27*(1-'Control Panel'!$B$27)^4*IFERROR(INDEX($AW6:$BT6,1,'Control Panel'!$B$8-4),0)+'Control Panel'!$B$27*(1-'Control Panel'!$B$27)^5*IFERROR(INDEX($AW6:$BT6,1,'Control Panel'!$B$8-5),0))/(1-(1-'Control Panel'!$B$27)^6))*Q6)+'Control Panel'!$B$19*((D6+M6*3)*Q6)+'Control Panel'!$B$20*(K6*Q6)+'Control Panel'!$B$21*(D6*(1+N6)^3*Q6)+'Control Panel'!$B$22*(I6*Q6)+'Control Panel'!$B$23*(T6*(1+IFERROR(D6/H6-1,0))))/'Control Panel'!$B$24,0) | AE6: =MAX(0,AB6*(1+U6+V6)) | AF6: =MAX(0,AC6*(1+U6+W6)) | AG6: =MAX(0,AD6*(1+U6+X6)) | AH6: =IFERROR(('Control Panel'!$B$33*AB6+'Control Panel'!$B$34*AE6+'Control Panel'!$B$35*(AB6*(1+L6+V6)))/('Control Panel'!$B$33+'Control Panel'!$B$34+'Control Panel'!$B$35),0) | AI6: =IFERROR(('Control Panel'!$B$33*AC6+'Control Panel'!$B$34*AF6+'Control Panel'!$B$35*(AC6*(1+L6+W6)))/('Control Panel'!$B$33+'Control Panel'!$B$34+'Control Panel'!$B$35),0) | AJ6: =IFERROR(('Control Panel'!$B$33*AD6+'Control Panel'!$B$34*AG6+'Control Panel'!$B$35*(AD6*(1+L6+X6)))/('Control Panel'!$B$33+'Control Panel'!$B$34+'Control Panel'!$B$35),0) | AK6: =AH6*'Control Panel'!$B$39+Y6 | AL6: =AI6*'Control Panel'!$B$39+Z6 | AM6: =AJ6*'Control Panel'!$B$39+AA6 | AN6: =AH6*'Control Panel'!$B$40+Y6 | AO6: =AI6*'Control Panel'!$B$40+Z6 | AP6: =AJ6*'Control Panel'!$B$40+AA6 | AQ6: =AH6*'Control Panel'!$B$41+Y6 | AR6: =AI6*'Control Panel'!$B$41+Z6 | AS6: =AJ6*'Control Panel'!$B$41+AA6 | AT6: =AH6*'Control Panel'!$B$42+Y6 | AU6: =AI6*'Control Panel'!$B$42+Z6 | AV6: =AJ6*'Control Panel'!$B$42+AA6 | AW6: =SUMIFS('Primary Sales History'!$C$4:$C$33,'Primary Sales History'!$A$4:$A$33,$A6,'Primary Sales History'!$B$4:$B$33,$B6) | AX6: =SUMIFS('Primary Sales History'!$D$4:$D$33,'Primary Sales History'!$A$4:$A$33,$A6,'Primary Sales History'!$B$4:$B$33,$B6) | AY6: =SUMIFS('Primary Sales History'!$E$4:$E$33,'Primary Sales History'!$A$4:$A$33,$A6,'Primary Sales History'!$B$4:$B$33,$B6) | AZ6: =SUMIFS('Primary Sales History'!$F$4:$F$33,'Primary Sales History'!$A$4:$A$33,$A6,'Primary Sales History'!$B$4:$B$33,$B6) | BA6: =SUMIFS('Primary Sales History'!$G$4:$G$33,'Primary Sales History'!$A$4:$A$33,$A6,'Primary Sales History'!$B$4:$B$33,$B6) | BB6: =SUMIFS('Primary Sales History'!$H$4:$H$33,'Primary Sales History'!$A$4:$A$33,$A6,'Primary Sales History'!$B$4:$B$33,$B6) | BC6: =SUMIFS('Primary Sales History'!$I$4:$I$33,'Primary Sales History'!$A$4:$A$33,$A6,'Primary Sales History'!$B$4:$B$33,$B6) | BD6: =SUMIFS('Primary Sales History'!$J$4:$J$33,'Primary Sales History'!$A$4:$A$33,$A6,'Primary Sales History'!$B$4:$B$33,$B6) | BE6: =SUMIFS('Primary Sales History'!$K$4:$K$33,'Primary Sales History'!$A$4:$A$33,$A6,'Primary Sales History'!$B$4:$B$33,$B6) | BF6: =SUMIFS('Primary Sales History'!$L$4:$L$33,'Primary Sales History'!$A$4:$A$33,$A6,'Primary Sales History'!$B$4:$B$33,$B6) | BG6: =SUMIFS('Primary Sales History'!$M$4:$M$33,'Primary Sales History'!$A$4:$A$33,$A6,'Primary Sales History'!$B$4:$B$33,$B6) | BH6: =SUMIFS('Primary Sales History'!$N$4:$N$33,'Primary Sales History'!$A$4:$A$33,$A6,'Primary Sales History'!$B$4:$B$33,$B6) | BI6: =SUMIFS('Primary Sales History'!$O$4:$O$33,'Primary Sales History'!$A$4:$A$33,$A6,'Primary Sales History'!$B$4:$B$33,$B6) | BJ6: =SUMIFS('Primary Sales History'!$P$4:$P$33,'Primary Sales History'!$A$4:$A$33,$A6,'Primary Sales History'!$B$4:$B$33,$B6) | BK6: 0 | BL6: 0 | BM6: 0 | BN6: 0 | BO6: 0 | BP6: 0 | BQ6: 0 | BR6: 0 | BS6: 0 | BT6: 0
A7: Mamaearth | B7: Body | C7: Body | D7: =IFERROR(INDEX($AW7:$BT7,1,'Control Panel'!$B$8-0),0) | E7: =IFERROR(INDEX($AW7:$BT7,1,'Control Panel'!$B$8-1),0) | F7: =IFERROR(INDEX($AW7:$BT7,1,'Control Panel'!$B$8-2),0) | G7: =IFERROR(INDEX($AW7:$BT7,1,'Control Panel'!$B$8-5),0) | H7: =IFERROR(INDEX($AW7:$BT7,1,'Control Panel'!$B$8-11),0) | I7: =AVERAGE(D7,E7,F7) | J7: =(D7+E7+F7+IFERROR(INDEX($AW7:$BT7,1,'Control Panel'!$B$8-3),0)+IFERROR(INDEX($AW7:$BT7,1,'Control Panel'!$B$8-4),0)+G7)/6 | K7: =(IFERROR(INDEX($AW7:$BT7,1,'Control Panel'!$B$8-0),0)+IFERROR(INDEX($AW7:$BT7,1,'Control Panel'!$B$8-1),0)+IFERROR(INDEX($AW7:$BT7,1,'Control Panel'!$B$8-2),0)+IFERROR(INDEX($AW7:$BT7,1,'Control Panel'!$B$8-3),0)+IFERROR(INDEX($AW7:$BT7,1,'Control Panel'!$B$8-4),0)+IFERROR(INDEX($AW7:$BT7,1,'Control Panel'!$B$8-5),0)+IFERROR(INDEX($AW7:$BT7,1,'Control Panel'!$B$8-6),0)+IFERROR(INDEX($AW7:$BT7,1,'Control Panel'!$B$8-7),0)+IFERROR(INDEX($AW7:$BT7,1,'Control Panel'!$B$8-8),0)+IFERROR(INDEX($AW7:$BT7,1,'Control Panel'!$B$8-9),0)+IFERROR(INDEX($AW7:$BT7,1,'Control Panel'!$B$8-10),0)+IFERROR(INDEX($AW7:$BT7,1,'Control Panel'!$B$8-11),0))/12 | L7: =IFERROR(MAX(-'Control Panel'!$B$36,MIN('Control Panel'!$B$36,(I7-J7)/J7)),0) | M7: =(D7-G7)/5 | N7: =IFERROR(IF(H7>0,(D7/H7)^(1/12)-1,0),0) | O7: =IFERROR((IFERROR(INDEX('Seasonality Matrix'!$B$4:$M$11,MATCH($C7,'Seasonality Matrix'!$A$4:$A$11,0),MATCH('Control Panel'!$B$12,'Seasonality Matrix'!$B$3:$M$3,0)),1))/(IFERROR(AVERAGE(INDEX('Seasonality Matrix'!$B$4:$M$11,MATCH($C7,'Seasonality Matrix'!$A$4:$A$11,0),0)),1)),1) | P7: =IFERROR((IFERROR(INDEX('Seasonality Matrix'!$B$4:$M$11,MATCH($C7,'Seasonality Matrix'!$A$4:$A$11,0),MATCH('Control Panel'!$B$13,'Seasonality Matrix'!$B$3:$M$3,0)),1))/(IFERROR(AVERAGE(INDEX('Seasonality Matrix'!$B$4:$M$11,MATCH($C7,'Seasonality Matrix'!$A$4:$A$11,0),0)),1)),1) | Q7: =IFERROR((IFERROR(INDEX('Seasonality Matrix'!$B$4:$M$11,MATCH($C7,'Seasonality Matrix'!$A$4:$A$11,0),MATCH('Control Panel'!$B$14,'Seasonality Matrix'!$B$3:$M$3,0)),1))/(IFERROR(AVERAGE(INDEX('Seasonality Matrix'!$B$4:$M$11,MATCH($C7,'Seasonality Matrix'!$A$4:$A$11,0),0)),1)),1) | R7: =IFERROR(INDEX($AW7:$BT7,1,'Control Panel'!$B$9-12),0) | S7: =IFERROR(INDEX($AW7:$BT7,1,'Control Panel'!$B$10-12),0) | T7: =IFERROR(INDEX($AW7:$BT7,1,'Control Panel'!$B$11-12),0) | U7: ='Control Panel'!$B$45 | V7: =IFERROR(SUMIFS('Promotion Calendar'!$G$4:$G$12,'Promotion Calendar'!$A$4:$A$12,$A7,'Promotion Calendar'!$B$4:$B$12,$B7,'Promotion Calendar'!$C$4:$C$12,'Control Panel'!$B$4),0) | W7: =IFERROR(SUMIFS('Promotion Calendar'!$G$4:$G$12,'Promotion Calendar'!$A$4:$A$12,$A7,'Promotion Calendar'!$B$4:$B$12,$B7,'Promotion Calendar'!$C$4:$C$12,'Control Panel'!$B$6),0) | X7: =IFERROR(SUMIFS('Promotion Calendar'!$G$4:$G$12,'Promotion Calendar'!$A$4:$A$12,$A7,'Promotion Calendar'!$B$4:$B$12,$B7,'Promotion Calendar'!$C$4:$C$12,'Control Panel'!$B$7),0) | Y7: =IFERROR(SUMIFS('NPI & EPD Planning'!$I$4:$I$10,'NPI & EPD Planning'!$A$4:$A$10,$A7,'NPI & EPD Planning'!$B$4:$B$10,$B7,'NPI & EPD Planning'!$D$4:$D$10,'Control Panel'!$B$4),0) | Z7: =IFERROR(SUMIFS('NPI & EPD Planning'!$I$4:$I$10,'NPI & EPD Planning'!$A$4:$A$10,$A7,'NPI & EPD Planning'!$B$4:$B$10,$B7,'NPI & EPD Planning'!$D$4:$D$10,'Control Panel'!$B$6),0) | AA7: =IFERROR(SUMIFS('NPI & EPD Planning'!$I$4:$I$10,'NPI & EPD Planning'!$A$4:$A$10,$A7,'NPI & EPD Planning'!$B$4:$B$10,$B7,'NPI & EPD Planning'!$D$4:$D$10,'Control Panel'!$B$7),0) | AB7: =IFERROR(('Control Panel'!$B$17*(('Control Panel'!$B$28*D7+'Control Panel'!$B$29*E7+'Control Panel'!$B$30*F7)*O7)+'Control Panel'!$B$18*((('Control Panel'!$B$27*(1-'Control Panel'!$B$27)^0*IFERROR(INDEX($AW7:$BT7,1,'Control Panel'!$B$8-0),0)+'Control Panel'!$B$27*(1-'Control Panel'!$B$27)^1*IFERROR(INDEX($AW7:$BT7,1,'Control Panel'!$B$8-1),0)+'Control Panel'!$B$27*(1-'Control Panel'!$B$27)^2*IFERROR(INDEX($AW7:$BT7,1,'Control Panel'!$B$8-2),0)+'Control Panel'!$B$27*(1-'Control Panel'!$B$27)^3*IFERROR(INDEX($AW7:$BT7,1,'Control Panel'!$B$8-3),0)+'Control Panel'!$B$27*(1-'Control Panel'!$B$27)^4*IFERROR(INDEX($AW7:$BT7,1,'Control Panel'!$B$8-4),0)+'Control Panel'!$B$27*(1-'Control Panel'!$B$27)^5*IFERROR(INDEX($AW7:$BT7,1,'Control Panel'!$B$8-5),0))/(1-(1-'Control Panel'!$B$27)^6))*O7)+'Control Panel'!$B$19*((D7+M7*1)*O7)+'Control Panel'!$B$20*(K7*O7)+'Control Panel'!$B$21*(D7*(1+N7)^1*O7)+'Control Panel'!$B$22*(I7*O7)+'Control Panel'!$B$23*(R7*(1+IFERROR(D7/H7-1,0))))/'Control Panel'!$B$24,0) | AC7: =IFERROR(('Control Panel'!$B$17*(('Control Panel'!$B$28*D7+'Control Panel'!$B$29*E7+'Control Panel'!$B$30*F7)*P7)+'Control Panel'!$B$18*((('Control Panel'!$B$27*(1-'Control Panel'!$B$27)^0*IFERROR(INDEX($AW7:$BT7,1,'Control Panel'!$B$8-0),0)+'Control Panel'!$B$27*(1-'Control Panel'!$B$27)^1*IFERROR(INDEX($AW7:$BT7,1,'Control Panel'!$B$8-1),0)+'Control Panel'!$B$27*(1-'Control Panel'!$B$27)^2*IFERROR(INDEX($AW7:$BT7,1,'Control Panel'!$B$8-2),0)+'Control Panel'!$B$27*(1-'Control Panel'!$B$27)^3*IFERROR(INDEX($AW7:$BT7,1,'Control Panel'!$B$8-3),0)+'Control Panel'!$B$27*(1-'Control Panel'!$B$27)^4*IFERROR(INDEX($AW7:$BT7,1,'Control Panel'!$B$8-4),0)+'Control Panel'!$B$27*(1-'Control Panel'!$B$27)^5*IFERROR(INDEX($AW7:$BT7,1,'Control Panel'!$B$8-5),0))/(1-(1-'Control Panel'!$B$27)^6))*P7)+'Control Panel'!$B$19*((D7+M7*2)*P7)+'Control Panel'!$B$20*(K7*P7)+'Control Panel'!$B$21*(D7*(1+N7)^2*P7)+'Control Panel'!$B$22*(I7*P7)+'Control Panel'!$B$23*(S7*(1+IFERROR(D7/H7-1,0))))/'Control Panel'!$B$24,0) | AD7: =IFERROR(('Control Panel'!$B$17*(('Control Panel'!$B$28*D7+'Control Panel'!$B$29*E7+'Control Panel'!$B$30*F7)*Q7)+'Control Panel'!$B$18*((('Control Panel'!$B$27*(1-'Control Panel'!$B$27)^0*IFERROR(INDEX($AW7:$BT7,1,'Control Panel'!$B$8-0),0)+'Control Panel'!$B$27*(1-'Control Panel'!$B$27)^1*IFERROR(INDEX($AW7:$BT7,1,'Control Panel'!$B$8-1),0)+'Control Panel'!$B$27*(1-'Control Panel'!$B$27)^2*IFERROR(INDEX($AW7:$BT7,1,'Control Panel'!$B$8-2),0)+'Control Panel'!$B$27*(1-'Control Panel'!$B$27)^3*IFERROR(INDEX($AW7:$BT7,1,'Control Panel'!$B$8-3),0)+'Control Panel'!$B$27*(1-'Control Panel'!$B$27)^4*IFERROR(INDEX($AW7:$BT7,1,'Control Panel'!$B$8-4),0)+'Control Panel'!$B$27*(1-'Control Panel'!$B$27)^5*IFERROR(INDEX($AW7:$BT7,1,'Control Panel'!$B$8-5),0))/(1-(1-'Control Panel'!$B$27)^6))*Q7)+'Control Panel'!$B$19*((D7+M7*3)*Q7)+'Control Panel'!$B$20*(K7*Q7)+'Control Panel'!$B$21*(D7*(1+N7)^3*Q7)+'Control Panel'!$B$22*(I7*Q7)+'Control Panel'!$B$23*(T7*(1+IFERROR(D7/H7-1,0))))/'Control Panel'!$B$24,0) | AE7: =MAX(0,AB7*(1+U7+V7)) | AF7: =MAX(0,AC7*(1+U7+W7)) | AG7: =MAX(0,AD7*(1+U7+X7)) | AH7: =IFERROR(('Control Panel'!$B$33*AB7+'Control Panel'!$B$34*AE7+'Control Panel'!$B$35*(AB7*(1+L7+V7)))/('Control Panel'!$B$33+'Control Panel'!$B$34+'Control Panel'!$B$35),0) | AI7: =IFERROR(('Control Panel'!$B$33*AC7+'Control Panel'!$B$34*AF7+'Control Panel'!$B$35*(AC7*(1+L7+W7)))/('Control Panel'!$B$33+'Control Panel'!$B$34+'Control Panel'!$B$35),0) | AJ7: =IFERROR(('Control Panel'!$B$33*AD7+'Control Panel'!$B$34*AG7+'Control Panel'!$B$35*(AD7*(1+L7+X7)))/('Control Panel'!$B$33+'Control Panel'!$B$34+'Control Panel'!$B$35),0) | AK7: =AH7*'Control Panel'!$B$39+Y7 | AL7: =AI7*'Control Panel'!$B$39+Z7 | AM7: =AJ7*'Control Panel'!$B$39+AA7 | AN7: =AH7*'Control Panel'!$B$40+Y7 | AO7: =AI7*'Control Panel'!$B$40+Z7 | AP7: =AJ7*'Control Panel'!$B$40+AA7 | AQ7: =AH7*'Control Panel'!$B$41+Y7 | AR7: =AI7*'Control Panel'!$B$41+Z7 | AS7: =AJ7*'Control Panel'!$B$41+AA7 | AT7: =AH7*'Control Panel'!$B$42+Y7 | AU7: =AI7*'Control Panel'!$B$42+Z7 | AV7: =AJ7*'Control Panel'!$B$42+AA7 | AW7: =SUMIFS('Primary Sales History'!$C$4:$C$33,'Primary Sales History'!$A$4:$A$33,$A7,'Primary Sales History'!$B$4:$B$33,$B7) | AX7: =SUMIFS('Primary Sales History'!$D$4:$D$33,'Primary Sales History'!$A$4:$A$33,$A7,'Primary Sales History'!$B$4:$B$33,$B7) | AY7: =SUMIFS('Primary Sales History'!$E$4:$E$33,'Primary Sales History'!$A$4:$A$33,$A7,'Primary Sales History'!$B$4:$B$33,$B7) | AZ7: =SUMIFS('Primary Sales History'!$F$4:$F$33,'Primary Sales History'!$A$4:$A$33,$A7,'Primary Sales History'!$B$4:$B$33,$B7) | BA7: =SUMIFS('Primary Sales History'!$G$4:$G$33,'Primary Sales History'!$A$4:$A$33,$A7,'Primary Sales History'!$B$4:$B$33,$B7) | BB7: =SUMIFS('Primary Sales History'!$H$4:$H$33,'Primary Sales History'!$A$4:$A$33,$A7,'Primary Sales History'!$B$4:$B$33,$B7) | BC7: =SUMIFS('Primary Sales History'!$I$4:$I$33,'Primary Sales History'!$A$4:$A$33,$A7,'Primary Sales History'!$B$4:$B$33,$B7) | BD7: =SUMIFS('Primary Sales History'!$J$4:$J$33,'Primary Sales History'!$A$4:$A$33,$A7,'Primary Sales History'!$B$4:$B$33,$B7) | BE7: =SUMIFS('Primary Sales History'!$K$4:$K$33,'Primary Sales History'!$A$4:$A$33,$A7,'Primary Sales History'!$B$4:$B$33,$B7) | BF7: =SUMIFS('Primary Sales History'!$L$4:$L$33,'Primary Sales History'!$A$4:$A$33,$A7,'Primary Sales History'!$B$4:$B$33,$B7) | BG7: =SUMIFS('Primary Sales History'!$M$4:$M$33,'Primary Sales History'!$A$4:$A$33,$A7,'Primary Sales History'!$B$4:$B$33,$B7) | BH7: =SUMIFS('Primary Sales History'!$N$4:$N$33,'Primary Sales History'!$A$4:$A$33,$A7,'Primary Sales History'!$B$4:$B$33,$B7) | BI7: =SUMIFS('Primary Sales History'!$O$4:$O$33,'Primary Sales History'!$A$4:$A$33,$A7,'Primary Sales History'!$B$4:$B$33,$B7) | BJ7: =SUMIFS('Primary Sales History'!$P$4:$P$33,'Primary Sales History'!$A$4:$A$33,$A7,'Primary Sales History'!$B$4:$B$33,$B7) | BK7: 0 | BL7: 0 | BM7: 0 | BN7: 0 | BO7: 0 | BP7: 0 | BQ7: 0 | BR7: 0 | BS7: 0 | BT7: 0
A8: Mamaearth | B8: Baby | C8: Baby | D8: =IFERROR(INDEX($AW8:$BT8,1,'Control Panel'!$B$8-0),0) | E8: =IFERROR(INDEX($AW8:$BT8,1,'Control Panel'!$B$8-1),0) | F8: =IFERROR(INDEX($AW8:$BT8,1,'Control Panel'!$B$8-2),0) | G8: =IFERROR(INDEX($AW8:$BT8,1,'Control Panel'!$B$8-5),0) | H8: =IFERROR(INDEX($AW8:$BT8,1,'Control Panel'!$B$8-11),0) | I8: =AVERAGE(D8,E8,F8) | J8: =(D8+E8+F8+IFERROR(INDEX($AW8:$BT8,1,'Control Panel'!$B$8-3),0)+IFERROR(INDEX($AW8:$BT8,1,'Control Panel'!$B$8-4),0)+G8)/6 | K8: =(IFERROR(INDEX($AW8:$BT8,1,'Control Panel'!$B$8-0),0)+IFERROR(INDEX($AW8:$BT8,1,'Control Panel'!$B$8-1),0)+IFERROR(INDEX($AW8:$BT8,1,'Control Panel'!$B$8-2),0)+IFERROR(INDEX($AW8:$BT8,1,'Control Panel'!$B$8-3),0)+IFERROR(INDEX($AW8:$BT8,1,'Control Panel'!$B$8-4),0)+IFERROR(INDEX($AW8:$BT8,1,'Control Panel'!$B$8-5),0)+IFERROR(INDEX($AW8:$BT8,1,'Control Panel'!$B$8-6),0)+IFERROR(INDEX($AW8:$BT8,1,'Control Panel'!$B$8-7),0)+IFERROR(INDEX($AW8:$BT8,1,'Control Panel'!$B$8-8),0)+IFERROR(INDEX($AW8:$BT8,1,'Control Panel'!$B$8-9),0)+IFERROR(INDEX($AW8:$BT8,1,'Control Panel'!$B$8-10),0)+IFERROR(INDEX($AW8:$BT8,1,'Control Panel'!$B$8-11),0))/12 | L8: =IFERROR(MAX(-'Control Panel'!$B$36,MIN('Control Panel'!$B$36,(I8-J8)/J8)),0) | M8: =(D8-G8)/5 | N8: =IFERROR(IF(H8>0,(D8/H8)^(1/12)-1,0),0) | O8: =IFERROR((IFERROR(INDEX('Seasonality Matrix'!$B$4:$M$11,MATCH($C8,'Seasonality Matrix'!$A$4:$A$11,0),MATCH('Control Panel'!$B$12,'Seasonality Matrix'!$B$3:$M$3,0)),1))/(IFERROR(AVERAGE(INDEX('Seasonality Matrix'!$B$4:$M$11,MATCH($C8,'Seasonality Matrix'!$A$4:$A$11,0),0)),1)),1) | P8: =IFERROR((IFERROR(INDEX('Seasonality Matrix'!$B$4:$M$11,MATCH($C8,'Seasonality Matrix'!$A$4:$A$11,0),MATCH('Control Panel'!$B$13,'Seasonality Matrix'!$B$3:$M$3,0)),1))/(IFERROR(AVERAGE(INDEX('Seasonality Matrix'!$B$4:$M$11,MATCH($C8,'Seasonality Matrix'!$A$4:$A$11,0),0)),1)),1) | Q8: =IFERROR((IFERROR(INDEX('Seasonality Matrix'!$B$4:$M$11,MATCH($C8,'Seasonality Matrix'!$A$4:$A$11,0),MATCH('Control Panel'!$B$14,'Seasonality Matrix'!$B$3:$M$3,0)),1))/(IFERROR(AVERAGE(INDEX('Seasonality Matrix'!$B$4:$M$11,MATCH($C8,'Seasonality Matrix'!$A$4:$A$11,0),0)),1)),1) | R8: =IFERROR(INDEX($AW8:$BT8,1,'Control Panel'!$B$9-12),0) | S8: =IFERROR(INDEX($AW8:$BT8,1,'Control Panel'!$B$10-12),0) | T8: =IFERROR(INDEX($AW8:$BT8,1,'Control Panel'!$B$11-12),0) | U8: ='Control Panel'!$B$45 | V8: =IFERROR(SUMIFS('Promotion Calendar'!$G$4:$G$12,'Promotion Calendar'!$A$4:$A$12,$A8,'Promotion Calendar'!$B$4:$B$12,$B8,'Promotion Calendar'!$C$4:$C$12,'Control Panel'!$B$4),0) | W8: =IFERROR(SUMIFS('Promotion Calendar'!$G$4:$G$12,'Promotion Calendar'!$A$4:$A$12,$A8,'Promotion Calendar'!$B$4:$B$12,$B8,'Promotion Calendar'!$C$4:$C$12,'Control Panel'!$B$6),0) | X8: =IFERROR(SUMIFS('Promotion Calendar'!$G$4:$G$12,'Promotion Calendar'!$A$4:$A$12,$A8,'Promotion Calendar'!$B$4:$B$12,$B8,'Promotion Calendar'!$C$4:$C$12,'Control Panel'!$B$7),0) | Y8: =IFERROR(SUMIFS('NPI & EPD Planning'!$I$4:$I$10,'NPI & EPD Planning'!$A$4:$A$10,$A8,'NPI & EPD Planning'!$B$4:$B$10,$B8,'NPI & EPD Planning'!$D$4:$D$10,'Control Panel'!$B$4),0) | Z8: =IFERROR(SUMIFS('NPI & EPD Planning'!$I$4:$I$10,'NPI & EPD Planning'!$A$4:$A$10,$A8,'NPI & EPD Planning'!$B$4:$B$10,$B8,'NPI & EPD Planning'!$D$4:$D$10,'Control Panel'!$B$6),0) | AA8: =IFERROR(SUMIFS('NPI & EPD Planning'!$I$4:$I$10,'NPI & EPD Planning'!$A$4:$A$10,$A8,'NPI & EPD Planning'!$B$4:$B$10,$B8,'NPI & EPD Planning'!$D$4:$D$10,'Control Panel'!$B$7),0) | AB8: =IFERROR(('Control Panel'!$B$17*(('Control Panel'!$B$28*D8+'Control Panel'!$B$29*E8+'Control Panel'!$B$30*F8)*O8)+'Control Panel'!$B$18*((('Control Panel'!$B$27*(1-'Control Panel'!$B$27)^0*IFERROR(INDEX($AW8:$BT8,1,'Control Panel'!$B$8-0),0)+'Control Panel'!$B$27*(1-'Control Panel'!$B$27)^1*IFERROR(INDEX($AW8:$BT8,1,'Control Panel'!$B$8-1),0)+'Control Panel'!$B$27*(1-'Control Panel'!$B$27)^2*IFERROR(INDEX($AW8:$BT8,1,'Control Panel'!$B$8-2),0)+'Control Panel'!$B$27*(1-'Control Panel'!$B$27)^3*IFERROR(INDEX($AW8:$BT8,1,'Control Panel'!$B$8-3),0)+'Control Panel'!$B$27*(1-'Control Panel'!$B$27)^4*IFERROR(INDEX($AW8:$BT8,1,'Control Panel'!$B$8-4),0)+'Control Panel'!$B$27*(1-'Control Panel'!$B$27)^5*IFERROR(INDEX($AW8:$BT8,1,'Control Panel'!$B$8-5),0))/(1-(1-'Control Panel'!$B$27)^6))*O8)+'Control Panel'!$B$19*((D8+M8*1)*O8)+'Control Panel'!$B$20*(K8*O8)+'Control Panel'!$B$21*(D8*(1+N8)^1*O8)+'Control Panel'!$B$22*(I8*O8)+'Control Panel'!$B$23*(R8*(1+IFERROR(D8/H8-1,0))))/'Control Panel'!$B$24,0) | AC8: =IFERROR(('Control Panel'!$B$17*(('Control Panel'!$B$28*D8+'Control Panel'!$B$29*E8+'Control Panel'!$B$30*F8)*P8)+'Control Panel'!$B$18*((('Control Panel'!$B$27*(1-'Control Panel'!$B$27)^0*IFERROR(INDEX($AW8:$BT8,1,'Control Panel'!$B$8-0),0)+'Control Panel'!$B$27*(1-'Control Panel'!$B$27)^1*IFERROR(INDEX($AW8:$BT8,1,'Control Panel'!$B$8-1),0)+'Control Panel'!$B$27*(1-'Control Panel'!$B$27)^2*IFERROR(INDEX($AW8:$BT8,1,'Control Panel'!$B$8-2),0)+'Control Panel'!$B$27*(1-'Control Panel'!$B$27)^3*IFERROR(INDEX($AW8:$BT8,1,'Control Panel'!$B$8-3),0)+'Control Panel'!$B$27*(1-'Control Panel'!$B$27)^4*IFERROR(INDEX($AW8:$BT8,1,'Control Panel'!$B$8-4),0)+'Control Panel'!$B$27*(1-'Control Panel'!$B$27)^5*IFERROR(INDEX($AW8:$BT8,1,'Control Panel'!$B$8-5),0))/(1-(1-'Control Panel'!$B$27)^6))*P8)+'Control Panel'!$B$19*((D8+M8*2)*P8)+'Control Panel'!$B$20*(K8*P8)+'Control Panel'!$B$21*(D8*(1+N8)^2*P8)+'Control Panel'!$B$22*(I8*P8)+'Control Panel'!$B$23*(S8*(1+IFERROR(D8/H8-1,0))))/'Control Panel'!$B$24,0) | AD8: =IFERROR(('Control Panel'!$B$17*(('Control Panel'!$B$28*D8+'Control Panel'!$B$29*E8+'Control Panel'!$B$30*F8)*Q8)+'Control Panel'!$B$18*((('Control Panel'!$B$27*(1-'Control Panel'!$B$27)^0*IFERROR(INDEX($AW8:$BT8,1,'Control Panel'!$B$8-0),0)+'Control Panel'!$B$27*(1-'Control Panel'!$B$27)^1*IFERROR(INDEX($AW8:$BT8,1,'Control Panel'!$B$8-1),0)+'Control Panel'!$B$27*(1-'Control Panel'!$B$27)^2*IFERROR(INDEX($AW8:$BT8,1,'Control Panel'!$B$8-2),0)+'Control Panel'!$B$27*(1-'Control Panel'!$B$27)^3*IFERROR(INDEX($AW8:$BT8,1,'Control Panel'!$B$8-3),0)+'Control Panel'!$B$27*(1-'Control Panel'!$B$27)^4*IFERROR(INDEX($AW8:$BT8,1,'Control Panel'!$B$8-4),0)+'Control Panel'!$B$27*(1-'Control Panel'!$B$27)^5*IFERROR(INDEX($AW8:$BT8,1,'Control Panel'!$B$8-5),0))/(1-(1-'Control Panel'!$B$27)^6))*Q8)+'Control Panel'!$B$19*((D8+M8*3)*Q8)+'Control Panel'!$B$20*(K8*Q8)+'Control Panel'!$B$21*(D8*(1+N8)^3*Q8)+'Control Panel'!$B$22*(I8*Q8)+'Control Panel'!$B$23*(T8*(1+IFERROR(D8/H8-1,0))))/'Control Panel'!$B$24,0) | AE8: =MAX(0,AB8*(1+U8+V8)) | AF8: =MAX(0,AC8*(1+U8+W8)) | AG8: =MAX(0,AD8*(1+U8+X8)) | AH8: =IFERROR(('Control Panel'!$B$33*AB8+'Control Panel'!$B$34*AE8+'Control Panel'!$B$35*(AB8*(1+L8+V8)))/('Control Panel'!$B$33+'Control Panel'!$B$34+'Control Panel'!$B$35),0) | AI8: =IFERROR(('Control Panel'!$B$33*AC8+'Control Panel'!$B$34*AF8+'Control Panel'!$B$35*(AC8*(1+L8+W8)))/('Control Panel'!$B$33+'Control Panel'!$B$34+'Control Panel'!$B$35),0) | AJ8: =IFERROR(('Control Panel'!$B$33*AD8+'Control Panel'!$B$34*AG8+'Control Panel'!$B$35*(AD8*(1+L8+X8)))/('Control Panel'!$B$33+'Control Panel'!$B$34+'Control Panel'!$B$35),0) | AK8: =AH8*'Control Panel'!$B$39+Y8 | AL8: =AI8*'Control Panel'!$B$39+Z8 | AM8: =AJ8*'Control Panel'!$B$39+AA8 | AN8: =AH8*'Control Panel'!$B$40+Y8 | AO8: =AI8*'Control Panel'!$B$40+Z8 | AP8: =AJ8*'Control Panel'!$B$40+AA8 | AQ8: =AH8*'Control Panel'!$B$41+Y8 | AR8: =AI8*'Control Panel'!$B$41+Z8 | AS8: =AJ8*'Control Panel'!$B$41+AA8 | AT8: =AH8*'Control Panel'!$B$42+Y8 | AU8: =AI8*'Control Panel'!$B$42+Z8 | AV8: =AJ8*'Control Panel'!$B$42+AA8 | AW8: =SUMIFS('Primary Sales History'!$C$4:$C$33,'Primary Sales History'!$A$4:$A$33,$A8,'Primary Sales History'!$B$4:$B$33,$B8) | AX8: =SUMIFS('Primary Sales History'!$D$4:$D$33,'Primary Sales History'!$A$4:$A$33,$A8,'Primary Sales History'!$B$4:$B$33,$B8) | AY8: =SUMIFS('Primary Sales History'!$E$4:$E$33,'Primary Sales History'!$A$4:$A$33,$A8,'Primary Sales History'!$B$4:$B$33,$B8) | AZ8: =SUMIFS('Primary Sales History'!$F$4:$F$33,'Primary Sales History'!$A$4:$A$33,$A8,'Primary Sales History'!$B$4:$B$33,$B8) | BA8: =SUMIFS('Primary Sales History'!$G$4:$G$33,'Primary Sales History'!$A$4:$A$33,$A8,'Primary Sales History'!$B$4:$B$33,$B8) | BB8: =SUMIFS('Primary Sales History'!$H$4:$H$33,'Primary Sales History'!$A$4:$A$33,$A8,'Primary Sales History'!$B$4:$B$33,$B8) | BC8: =SUMIFS('Primary Sales History'!$I$4:$I$33,'Primary Sales History'!$A$4:$A$33,$A8,'Primary Sales History'!$B$4:$B$33,$B8) | BD8: =SUMIFS('Primary Sales History'!$J$4:$J$33,'Primary Sales History'!$A$4:$A$33,$A8,'Primary Sales History'!$B$4:$B$33,$B8) | BE8: =SUMIFS('Primary Sales History'!$K$4:$K$33,'Primary Sales History'!$A$4:$A$33,$A8,'Primary Sales History'!$B$4:$B$33,$B8) | BF8: =SUMIFS('Primary Sales History'!$L$4:$L$33,'Primary Sales History'!$A$4:$A$33,$A8,'Primary Sales History'!$B$4:$B$33,$B8) | BG8: =SUMIFS('Primary Sales History'!$M$4:$M$33,'Primary Sales History'!$A$4:$A$33,$A8,'Primary Sales History'!$B$4:$B$33,$B8) | BH8: =SUMIFS('Primary Sales History'!$N$4:$N$33,'Primary Sales History'!$A$4:$A$33,$A8,'Primary Sales History'!$B$4:$B$33,$B8) | BI8: =SUMIFS('Primary Sales History'!$O$4:$O$33,'Primary Sales History'!$A$4:$A$33,$A8,'Primary Sales History'!$B$4:$B$33,$B8) | BJ8: =SUMIFS('Primary Sales History'!$P$4:$P$33,'Primary Sales History'!$A$4:$A$33,$A8,'Primary Sales History'!$B$4:$B$33,$B8) | BK8: 0 | BL8: 0 | BM8: 0 | BN8: 0 | BO8: 0 | BP8: 0 | BQ8: 0 | BR8: 0 | BS8: 0 | BT8: 0
